[2021-07-11 11:29:45 +0000] [7] [INFO] Starting gunicorn 20.1.0
[2021-07-11 11:29:45 +0000] [7] [INFO] Listening at: http://0.0.0.0:5002 (7)
[2021-07-11 11:29:45 +0000] [7] [INFO] Using worker: gthread
[2021-07-11 11:29:45 +0000] [9] [INFO] Booting worker with pid: 9
[2021-07-11 11:29:45 +0000] [10] [INFO] Booting worker with pid: 10
[2021-07-11 12:23:21 +0000] [8] [INFO] Starting gunicorn 20.1.0
[2021-07-11 12:23:21 +0000] [8] [INFO] Listening at: http://0.0.0.0:5002 (8)
[2021-07-11 12:23:21 +0000] [8] [INFO] Using worker: gthread
[2021-07-11 12:23:21 +0000] [10] [INFO] Booting worker with pid: 10
[2021-07-11 12:23:21 +0000] [11] [INFO] Booting worker with pid: 11
[2021-07-11 12:31:50 +0000] [7] [INFO] Starting gunicorn 20.1.0
[2021-07-11 12:31:50 +0000] [7] [INFO] Listening at: http://0.0.0.0:5002 (7)
[2021-07-11 12:31:50 +0000] [7] [INFO] Using worker: gthread
[2021-07-11 12:31:50 +0000] [9] [INFO] Booting worker with pid: 9
[2021-07-11 12:31:50 +0000] [10] [INFO] Booting worker with pid: 10
[2021-07-11 12:36:49 +0000] [7] [INFO] Starting gunicorn 20.1.0
[2021-07-11 12:36:49 +0000] [7] [INFO] Listening at: http://0.0.0.0:5002 (7)
[2021-07-11 12:36:49 +0000] [7] [INFO] Using worker: gthread
[2021-07-11 12:36:49 +0000] [9] [INFO] Booting worker with pid: 9
[2021-07-11 12:36:49 +0000] [10] [INFO] Booting worker with pid: 10
[2021-07-11 12:46:32 +0000] [8] [INFO] Starting gunicorn 20.1.0
[2021-07-11 12:46:32 +0000] [8] [INFO] Listening at: http://0.0.0.0:5002 (8)
[2021-07-11 12:46:32 +0000] [8] [INFO] Using worker: gthread
[2021-07-11 12:46:32 +0000] [10] [INFO] Booting worker with pid: 10
[2021-07-11 12:46:32 +0000] [11] [INFO] Booting worker with pid: 11
[2021-07-11 14:46:32 +0000] [7] [INFO] Starting gunicorn 20.1.0
[2021-07-11 14:46:32 +0000] [7] [INFO] Listening at: http://0.0.0.0:5002 (7)
[2021-07-11 14:46:32 +0000] [7] [INFO] Using worker: gthread
[2021-07-11 14:46:32 +0000] [9] [INFO] Booting worker with pid: 9
[2021-07-11 14:46:32 +0000] [10] [INFO] Booting worker with pid: 10
[2021-07-11 14:59:27,076] ERROR in app: Exception on /upload [POST]
Traceback (most recent call last):
  File "/usr/local/lib/python3.8/site-packages/flask/app.py", line 2070, in wsgi_app
    response = self.full_dispatch_request()
  File "/usr/local/lib/python3.8/site-packages/flask/app.py", line 1515, in full_dispatch_request
    rv = self.handle_user_exception(e)
  File "/usr/local/lib/python3.8/site-packages/flask_cors/extension.py", line 165, in wrapped_function
    return cors_after_request(app.make_response(f(*args, **kwargs)))
  File "/usr/local/lib/python3.8/site-packages/flask/app.py", line 1513, in full_dispatch_request
    rv = self.dispatch_request()
  File "/usr/local/lib/python3.8/site-packages/flask/app.py", line 1499, in dispatch_request
    return self.ensure_sync(self.view_functions[rule.endpoint])(**req.view_args)
  File "/usr/local/lib/python3.8/site-packages/flask_jwt_extended/view_decorators.py", line 125, in decorator
    return current_app.ensure_sync(fn)(*args, **kwargs)
  File "/app/app/routes.py", line 105, in upload_file
    if cardUpdate.brand_image is None:
AttributeError: 'NoneType' object has no attribute 'brand_image'
[2021-07-11 14:59:34,794] ERROR in app: Exception on /upload [POST]
Traceback (most recent call last):
  File "/usr/local/lib/python3.8/site-packages/flask/app.py", line 2070, in wsgi_app
    response = self.full_dispatch_request()
  File "/usr/local/lib/python3.8/site-packages/flask/app.py", line 1515, in full_dispatch_request
    rv = self.handle_user_exception(e)
  File "/usr/local/lib/python3.8/site-packages/flask_cors/extension.py", line 165, in wrapped_function
    return cors_after_request(app.make_response(f(*args, **kwargs)))
  File "/usr/local/lib/python3.8/site-packages/flask/app.py", line 1513, in full_dispatch_request
    rv = self.dispatch_request()
  File "/usr/local/lib/python3.8/site-packages/flask/app.py", line 1499, in dispatch_request
    return self.ensure_sync(self.view_functions[rule.endpoint])(**req.view_args)
  File "/usr/local/lib/python3.8/site-packages/flask_jwt_extended/view_decorators.py", line 125, in decorator
    return current_app.ensure_sync(fn)(*args, **kwargs)
  File "/app/app/routes.py", line 105, in upload_file
    if cardUpdate.brand_image is None:
AttributeError: 'NoneType' object has no attribute 'brand_image'
[2021-07-11 15:01:03,863] ERROR in app: Exception on /upload [POST]
Traceback (most recent call last):
  File "/usr/local/lib/python3.8/site-packages/flask/app.py", line 2070, in wsgi_app
    response = self.full_dispatch_request()
  File "/usr/local/lib/python3.8/site-packages/flask/app.py", line 1515, in full_dispatch_request
    rv = self.handle_user_exception(e)
  File "/usr/local/lib/python3.8/site-packages/flask_cors/extension.py", line 165, in wrapped_function
    return cors_after_request(app.make_response(f(*args, **kwargs)))
  File "/usr/local/lib/python3.8/site-packages/flask/app.py", line 1513, in full_dispatch_request
    rv = self.dispatch_request()
  File "/usr/local/lib/python3.8/site-packages/flask/app.py", line 1499, in dispatch_request
    return self.ensure_sync(self.view_functions[rule.endpoint])(**req.view_args)
  File "/usr/local/lib/python3.8/site-packages/flask_jwt_extended/view_decorators.py", line 125, in decorator
    return current_app.ensure_sync(fn)(*args, **kwargs)
  File "/app/app/routes.py", line 105, in upload_file
    if cardUpdate.brand_image is None:
AttributeError: 'NoneType' object has no attribute 'brand_image'
[2021-07-11 15:02:56,975] ERROR in app: Exception on /upload [POST]
Traceback (most recent call last):
  File "/usr/local/lib/python3.8/site-packages/flask/app.py", line 2070, in wsgi_app
    response = self.full_dispatch_request()
  File "/usr/local/lib/python3.8/site-packages/flask/app.py", line 1515, in full_dispatch_request
    rv = self.handle_user_exception(e)
  File "/usr/local/lib/python3.8/site-packages/flask_cors/extension.py", line 165, in wrapped_function
    return cors_after_request(app.make_response(f(*args, **kwargs)))
  File "/usr/local/lib/python3.8/site-packages/flask/app.py", line 1513, in full_dispatch_request
    rv = self.dispatch_request()
  File "/usr/local/lib/python3.8/site-packages/flask/app.py", line 1499, in dispatch_request
    return self.ensure_sync(self.view_functions[rule.endpoint])(**req.view_args)
  File "/usr/local/lib/python3.8/site-packages/flask_jwt_extended/view_decorators.py", line 125, in decorator
    return current_app.ensure_sync(fn)(*args, **kwargs)
  File "/app/app/routes.py", line 105, in upload_file
    if cardUpdate.brand_image is None:
AttributeError: 'NoneType' object has no attribute 'brand_image'
[2021-07-11 15:03:31,719] ERROR in app: Exception on /upload [POST]
Traceback (most recent call last):
  File "/usr/local/lib/python3.8/site-packages/flask/app.py", line 2070, in wsgi_app
    response = self.full_dispatch_request()
  File "/usr/local/lib/python3.8/site-packages/flask/app.py", line 1515, in full_dispatch_request
    rv = self.handle_user_exception(e)
  File "/usr/local/lib/python3.8/site-packages/flask_cors/extension.py", line 165, in wrapped_function
    return cors_after_request(app.make_response(f(*args, **kwargs)))
  File "/usr/local/lib/python3.8/site-packages/flask/app.py", line 1513, in full_dispatch_request
    rv = self.dispatch_request()
  File "/usr/local/lib/python3.8/site-packages/flask/app.py", line 1499, in dispatch_request
    return self.ensure_sync(self.view_functions[rule.endpoint])(**req.view_args)
  File "/usr/local/lib/python3.8/site-packages/flask_jwt_extended/view_decorators.py", line 125, in decorator
    return current_app.ensure_sync(fn)(*args, **kwargs)
  File "/app/app/routes.py", line 105, in upload_file
AttributeError: 'NoneType' object has no attribute 'brand_image'
[2021-07-11 15:04:45 +0000] [7] [INFO] Starting gunicorn 20.1.0
[2021-07-11 15:04:45 +0000] [7] [INFO] Listening at: http://0.0.0.0:5002 (7)
[2021-07-11 15:04:45 +0000] [7] [INFO] Using worker: gthread
[2021-07-11 15:04:45 +0000] [9] [INFO] Booting worker with pid: 9
[2021-07-11 15:04:45 +0000] [10] [INFO] Booting worker with pid: 10
[2021-07-11 15:05:14,148] ERROR in app: Exception on /upload [POST]
Traceback (most recent call last):
  File "/usr/local/lib/python3.8/site-packages/flask/app.py", line 2070, in wsgi_app
    response = self.full_dispatch_request()
  File "/usr/local/lib/python3.8/site-packages/flask/app.py", line 1515, in full_dispatch_request
    rv = self.handle_user_exception(e)
  File "/usr/local/lib/python3.8/site-packages/flask_cors/extension.py", line 165, in wrapped_function
    return cors_after_request(app.make_response(f(*args, **kwargs)))
  File "/usr/local/lib/python3.8/site-packages/flask/app.py", line 1513, in full_dispatch_request
    rv = self.dispatch_request()
  File "/usr/local/lib/python3.8/site-packages/flask/app.py", line 1499, in dispatch_request
    return self.ensure_sync(self.view_functions[rule.endpoint])(**req.view_args)
  File "/usr/local/lib/python3.8/site-packages/flask_jwt_extended/view_decorators.py", line 125, in decorator
    return current_app.ensure_sync(fn)(*args, **kwargs)
  File "/app/app/routes.py", line 106, in upload_file
    if cardUpdate.brand_image is None:
AttributeError: 'NoneType' object has no attribute 'brand_image'
[2021-07-11 15:11:18,878] ERROR in app: Exception on /upload [POST]
Traceback (most recent call last):
  File "/usr/local/lib/python3.8/site-packages/flask/app.py", line 2070, in wsgi_app
    response = self.full_dispatch_request()
  File "/usr/local/lib/python3.8/site-packages/flask/app.py", line 1515, in full_dispatch_request
    rv = self.handle_user_exception(e)
  File "/usr/local/lib/python3.8/site-packages/flask_cors/extension.py", line 165, in wrapped_function
    return cors_after_request(app.make_response(f(*args, **kwargs)))
  File "/usr/local/lib/python3.8/site-packages/flask/app.py", line 1513, in full_dispatch_request
    rv = self.dispatch_request()
  File "/usr/local/lib/python3.8/site-packages/flask/app.py", line 1499, in dispatch_request
    return self.ensure_sync(self.view_functions[rule.endpoint])(**req.view_args)
  File "/usr/local/lib/python3.8/site-packages/flask_jwt_extended/view_decorators.py", line 125, in decorator
    return current_app.ensure_sync(fn)(*args, **kwargs)
  File "/app/app/routes.py", line 106, in upload_file
    img_sizes = [(128,128),(256,256)]
AttributeError: 'NoneType' object has no attribute 'brand_image'
