[2021-07-11 07:41:04 +0000] [8] [INFO] Starting gunicorn 20.1.0
[2021-07-11 07:41:04 +0000] [8] [INFO] Listening at: http://0.0.0.0:5000 (8)
[2021-07-11 07:41:04 +0000] [8] [INFO] Using worker: gthread
[2021-07-11 07:41:04 +0000] [10] [INFO] Booting worker with pid: 10
[2021-07-11 07:41:04 +0000] [11] [INFO] Booting worker with pid: 11
[2021-07-11 08:23:43 +0000] [8] [INFO] Starting gunicorn 20.1.0
[2021-07-11 08:23:43 +0000] [8] [INFO] Listening at: http://0.0.0.0:5000 (8)
[2021-07-11 08:23:43 +0000] [8] [INFO] Using worker: gthread
[2021-07-11 08:23:43 +0000] [10] [INFO] Booting worker with pid: 10
[2021-07-11 08:23:43 +0000] [11] [INFO] Booting worker with pid: 11
[2021-07-11 08:24:41 +0000] [8] [INFO] Handling signal: term
[2021-07-11 08:24:42 +0000] [11] [INFO] Worker exiting (pid: 11)
[2021-07-11 08:24:42 +0000] [10] [INFO] Worker exiting (pid: 10)
[2021-07-11 08:24:42 +0000] [8] [INFO] Shutting down: Master
[2021-07-11 08:39:58 +0000] [9] [INFO] Starting gunicorn 20.1.0
[2021-07-11 08:39:58 +0000] [9] [INFO] Listening at: http://0.0.0.0:5000 (9)
[2021-07-11 08:39:58 +0000] [9] [INFO] Using worker: gthread
[2021-07-11 08:39:58 +0000] [11] [INFO] Booting worker with pid: 11
[2021-07-11 08:39:58 +0000] [12] [INFO] Booting worker with pid: 12
[2021-07-11 12:23:21 +0000] [9] [INFO] Starting gunicorn 20.1.0
[2021-07-11 12:23:21 +0000] [9] [INFO] Listening at: http://0.0.0.0:5000 (9)
[2021-07-11 12:23:21 +0000] [9] [INFO] Using worker: gthread
[2021-07-11 12:23:22 +0000] [11] [INFO] Booting worker with pid: 11
[2021-07-11 12:23:22 +0000] [12] [INFO] Booting worker with pid: 12
[2021-07-11 12:30:36 +0000] [7] [INFO] Starting gunicorn 20.1.0
[2021-07-11 12:30:36 +0000] [7] [INFO] Listening at: http://0.0.0.0:5000 (7)
[2021-07-11 12:30:36 +0000] [7] [INFO] Using worker: gthread
[2021-07-11 12:30:36 +0000] [9] [INFO] Booting worker with pid: 9
[2021-07-11 12:30:36 +0000] [10] [INFO] Booting worker with pid: 10
[2021-07-11 14:42:20 +0000] [7] [INFO] Starting gunicorn 20.1.0
[2021-07-11 14:42:20 +0000] [7] [INFO] Listening at: http://0.0.0.0:5000 (7)
[2021-07-11 14:42:20 +0000] [7] [INFO] Using worker: gthread
[2021-07-11 14:42:20 +0000] [9] [INFO] Booting worker with pid: 9
[2021-07-11 14:42:20 +0000] [10] [INFO] Booting worker with pid: 10
[2021-08-01 04:12:06 +0000] [7] [INFO] Starting gunicorn 20.1.0
[2021-08-01 04:12:06 +0000] [7] [INFO] Listening at: http://0.0.0.0:5000 (7)
[2021-08-01 04:12:06 +0000] [7] [INFO] Using worker: gthread
[2021-08-01 04:12:06 +0000] [9] [INFO] Booting worker with pid: 9
[2021-08-01 04:12:06 +0000] [10] [INFO] Booting worker with pid: 10
[2021-08-01 05:19:38,351] ERROR in app: Exception on /login [POST]
Traceback (most recent call last):
  File "/usr/local/lib/python3.8/site-packages/sqlalchemy/engine/base.py", line 1771, in _execute_context
    self.dialect.do_execute(
  File "/usr/local/lib/python3.8/site-packages/sqlalchemy/engine/default.py", line 717, in do_execute
    cursor.execute(statement, parameters)
psycopg2.OperationalError: SSL SYSCALL error: EOF detected


The above exception was the direct cause of the following exception:

Traceback (most recent call last):
  File "/usr/local/lib/python3.8/site-packages/flask/app.py", line 2070, in wsgi_app
    response = self.full_dispatch_request()
  File "/usr/local/lib/python3.8/site-packages/flask/app.py", line 1515, in full_dispatch_request
    rv = self.handle_user_exception(e)
  File "/usr/local/lib/python3.8/site-packages/flask_cors/extension.py", line 165, in wrapped_function
    return cors_after_request(app.make_response(f(*args, **kwargs)))
  File "/usr/local/lib/python3.8/site-packages/flask/app.py", line 1513, in full_dispatch_request
    rv = self.dispatch_request()
  File "/usr/local/lib/python3.8/site-packages/flask/app.py", line 1499, in dispatch_request
    return self.ensure_sync(self.view_functions[rule.endpoint])(**req.view_args)
  File "/app/app/routes.py", line 27, in login
    user = User.query.filter_by(email=email).first()
  File "/usr/local/lib/python3.8/site-packages/sqlalchemy/orm/query.py", line 2763, in first
    return self.limit(1)._iter().first()
  File "/usr/local/lib/python3.8/site-packages/sqlalchemy/orm/query.py", line 2847, in _iter
    result = self.session.execute(
  File "/usr/local/lib/python3.8/site-packages/sqlalchemy/orm/session.py", line 1689, in execute
    result = conn._execute_20(statement, params or {}, execution_options)
  File "/usr/local/lib/python3.8/site-packages/sqlalchemy/engine/base.py", line 1583, in _execute_20
    return meth(self, args_10style, kwargs_10style, execution_options)
  File "/usr/local/lib/python3.8/site-packages/sqlalchemy/sql/elements.py", line 323, in _execute_on_connection
    return connection._execute_clauseelement(
  File "/usr/local/lib/python3.8/site-packages/sqlalchemy/engine/base.py", line 1452, in _execute_clauseelement
    ret = self._execute_context(
  File "/usr/local/lib/python3.8/site-packages/sqlalchemy/engine/base.py", line 1814, in _execute_context
    self._handle_dbapi_exception(
  File "/usr/local/lib/python3.8/site-packages/sqlalchemy/engine/base.py", line 1995, in _handle_dbapi_exception
    util.raise_(
  File "/usr/local/lib/python3.8/site-packages/sqlalchemy/util/compat.py", line 207, in raise_
    raise exception
  File "/usr/local/lib/python3.8/site-packages/sqlalchemy/engine/base.py", line 1771, in _execute_context
    self.dialect.do_execute(
  File "/usr/local/lib/python3.8/site-packages/sqlalchemy/engine/default.py", line 717, in do_execute
    cursor.execute(statement, parameters)
sqlalchemy.exc.OperationalError: (psycopg2.OperationalError) SSL SYSCALL error: EOF detected

[SQL: SELECT camp_users.id AS camp_users_id, camp_users.email AS camp_users_email, camp_users.mobile AS camp_users_mobile, camp_users.user_name AS camp_users_user_name, camp_users.password_hash AS camp_users_password_hash, camp_users.country AS camp_users_country, camp_users.created_at AS camp_users_created_at, camp_users.updated_at AS camp_users_updated_at 
FROM camp_users 
WHERE camp_users.email = %(email_1)s 
 LIMIT %(param_1)s]
[parameters: {'email_1': 'admin@example.com', 'param_1': 1}]
(Background on this error at: https://sqlalche.me/e/14/e3q8)
[2021-08-01 06:04:15,620] ERROR in app: Exception on /login [POST]
Traceback (most recent call last):
  File "/usr/local/lib/python3.8/site-packages/sqlalchemy/engine/base.py", line 1771, in _execute_context
    self.dialect.do_execute(
  File "/usr/local/lib/python3.8/site-packages/sqlalchemy/engine/default.py", line 717, in do_execute
    cursor.execute(statement, parameters)
psycopg2.OperationalError: SSL SYSCALL error: EOF detected


The above exception was the direct cause of the following exception:

Traceback (most recent call last):
  File "/usr/local/lib/python3.8/site-packages/flask/app.py", line 2070, in wsgi_app
    response = self.full_dispatch_request()
  File "/usr/local/lib/python3.8/site-packages/flask/app.py", line 1515, in full_dispatch_request
    rv = self.handle_user_exception(e)
  File "/usr/local/lib/python3.8/site-packages/flask_cors/extension.py", line 165, in wrapped_function
    return cors_after_request(app.make_response(f(*args, **kwargs)))
  File "/usr/local/lib/python3.8/site-packages/flask/app.py", line 1513, in full_dispatch_request
    rv = self.dispatch_request()
  File "/usr/local/lib/python3.8/site-packages/flask/app.py", line 1499, in dispatch_request
    return self.ensure_sync(self.view_functions[rule.endpoint])(**req.view_args)
  File "/app/app/routes.py", line 27, in login
    user = User.query.filter_by(email=email).first()
  File "/usr/local/lib/python3.8/site-packages/sqlalchemy/orm/query.py", line 2763, in first
    return self.limit(1)._iter().first()
  File "/usr/local/lib/python3.8/site-packages/sqlalchemy/orm/query.py", line 2847, in _iter
    result = self.session.execute(
  File "/usr/local/lib/python3.8/site-packages/sqlalchemy/orm/session.py", line 1689, in execute
    result = conn._execute_20(statement, params or {}, execution_options)
  File "/usr/local/lib/python3.8/site-packages/sqlalchemy/engine/base.py", line 1583, in _execute_20
    return meth(self, args_10style, kwargs_10style, execution_options)
  File "/usr/local/lib/python3.8/site-packages/sqlalchemy/sql/elements.py", line 323, in _execute_on_connection
    return connection._execute_clauseelement(
  File "/usr/local/lib/python3.8/site-packages/sqlalchemy/engine/base.py", line 1452, in _execute_clauseelement
    ret = self._execute_context(
  File "/usr/local/lib/python3.8/site-packages/sqlalchemy/engine/base.py", line 1814, in _execute_context
    self._handle_dbapi_exception(
  File "/usr/local/lib/python3.8/site-packages/sqlalchemy/engine/base.py", line 1995, in _handle_dbapi_exception
    util.raise_(
  File "/usr/local/lib/python3.8/site-packages/sqlalchemy/util/compat.py", line 207, in raise_
    raise exception
  File "/usr/local/lib/python3.8/site-packages/sqlalchemy/engine/base.py", line 1771, in _execute_context
    self.dialect.do_execute(
  File "/usr/local/lib/python3.8/site-packages/sqlalchemy/engine/default.py", line 717, in do_execute
    cursor.execute(statement, parameters)
sqlalchemy.exc.OperationalError: (psycopg2.OperationalError) SSL SYSCALL error: EOF detected

[SQL: SELECT camp_users.id AS camp_users_id, camp_users.email AS camp_users_email, camp_users.mobile AS camp_users_mobile, camp_users.user_name AS camp_users_user_name, camp_users.password_hash AS camp_users_password_hash, camp_users.country AS camp_users_country, camp_users.created_at AS camp_users_created_at, camp_users.updated_at AS camp_users_updated_at 
FROM camp_users 
WHERE camp_users.email = %(email_1)s 
 LIMIT %(param_1)s]
[parameters: {'email_1': 'admin@example.com', 'param_1': 1}]
(Background on this error at: https://sqlalche.me/e/14/e3q8)
[2021-08-01 06:26:32,266] ERROR in app: Exception on /login [POST]
Traceback (most recent call last):
  File "/usr/local/lib/python3.8/site-packages/sqlalchemy/engine/base.py", line 1771, in _execute_context
    self.dialect.do_execute(
  File "/usr/local/lib/python3.8/site-packages/sqlalchemy/engine/default.py", line 717, in do_execute
    cursor.execute(statement, parameters)
psycopg2.OperationalError: SSL SYSCALL error: EOF detected


The above exception was the direct cause of the following exception:

Traceback (most recent call last):
  File "/usr/local/lib/python3.8/site-packages/flask/app.py", line 2070, in wsgi_app
    response = self.full_dispatch_request()
  File "/usr/local/lib/python3.8/site-packages/flask/app.py", line 1515, in full_dispatch_request
    rv = self.handle_user_exception(e)
  File "/usr/local/lib/python3.8/site-packages/flask_cors/extension.py", line 165, in wrapped_function
    return cors_after_request(app.make_response(f(*args, **kwargs)))
  File "/usr/local/lib/python3.8/site-packages/flask/app.py", line 1513, in full_dispatch_request
    rv = self.dispatch_request()
  File "/usr/local/lib/python3.8/site-packages/flask/app.py", line 1499, in dispatch_request
    return self.ensure_sync(self.view_functions[rule.endpoint])(**req.view_args)
  File "/app/app/routes.py", line 27, in login
    user = User.query.filter_by(email=email).first()
  File "/usr/local/lib/python3.8/site-packages/sqlalchemy/orm/query.py", line 2763, in first
    return self.limit(1)._iter().first()
  File "/usr/local/lib/python3.8/site-packages/sqlalchemy/orm/query.py", line 2847, in _iter
    result = self.session.execute(
  File "/usr/local/lib/python3.8/site-packages/sqlalchemy/orm/session.py", line 1689, in execute
    result = conn._execute_20(statement, params or {}, execution_options)
  File "/usr/local/lib/python3.8/site-packages/sqlalchemy/engine/base.py", line 1583, in _execute_20
    return meth(self, args_10style, kwargs_10style, execution_options)
  File "/usr/local/lib/python3.8/site-packages/sqlalchemy/sql/elements.py", line 323, in _execute_on_connection
    return connection._execute_clauseelement(
  File "/usr/local/lib/python3.8/site-packages/sqlalchemy/engine/base.py", line 1452, in _execute_clauseelement
    ret = self._execute_context(
  File "/usr/local/lib/python3.8/site-packages/sqlalchemy/engine/base.py", line 1814, in _execute_context
    self._handle_dbapi_exception(
  File "/usr/local/lib/python3.8/site-packages/sqlalchemy/engine/base.py", line 1995, in _handle_dbapi_exception
    util.raise_(
  File "/usr/local/lib/python3.8/site-packages/sqlalchemy/util/compat.py", line 207, in raise_
    raise exception
  File "/usr/local/lib/python3.8/site-packages/sqlalchemy/engine/base.py", line 1771, in _execute_context
    self.dialect.do_execute(
  File "/usr/local/lib/python3.8/site-packages/sqlalchemy/engine/default.py", line 717, in do_execute
    cursor.execute(statement, parameters)
sqlalchemy.exc.OperationalError: (psycopg2.OperationalError) SSL SYSCALL error: EOF detected

[SQL: SELECT camp_users.id AS camp_users_id, camp_users.email AS camp_users_email, camp_users.mobile AS camp_users_mobile, camp_users.user_name AS camp_users_user_name, camp_users.password_hash AS camp_users_password_hash, camp_users.country AS camp_users_country, camp_users.created_at AS camp_users_created_at, camp_users.updated_at AS camp_users_updated_at 
FROM camp_users 
WHERE camp_users.email = %(email_1)s 
 LIMIT %(param_1)s]
[parameters: {'email_1': 'admin@example.com', 'param_1': 1}]
(Background on this error at: https://sqlalche.me/e/14/e3q8)
[2021-08-01 07:34:04 +0000] [7] [INFO] Starting gunicorn 20.1.0
[2021-08-01 07:34:04 +0000] [7] [INFO] Listening at: http://0.0.0.0:5000 (7)
[2021-08-01 07:34:04 +0000] [7] [INFO] Using worker: gthread
[2021-08-01 07:34:04 +0000] [9] [INFO] Booting worker with pid: 9
[2021-08-01 07:34:04 +0000] [10] [INFO] Booting worker with pid: 10
[2021-08-01 07:34:04 +0000] [10] [ERROR] Exception in worker process
Traceback (most recent call last):
  File "/usr/local/lib/python3.8/site-packages/gunicorn/arbiter.py", line 589, in spawn_worker
    worker.init_process()
  File "/usr/local/lib/python3.8/site-packages/gunicorn/workers/gthread.py", line 92, in init_process
    super().init_process()
  File "/usr/local/lib/python3.8/site-packages/gunicorn/workers/base.py", line 134, in init_process
    self.load_wsgi()
  File "/usr/local/lib/python3.8/site-packages/gunicorn/workers/base.py", line 146, in load_wsgi
    self.wsgi = self.app.wsgi()
  File "/usr/local/lib/python3.8/site-packages/gunicorn/app/base.py", line 67, in wsgi
    self.callable = self.load()
  File "/usr/local/lib/python3.8/site-packages/gunicorn/app/wsgiapp.py", line 58, in load
    return self.load_wsgiapp()
  File "/usr/local/lib/python3.8/site-packages/gunicorn/app/wsgiapp.py", line 48, in load_wsgiapp
    return util.import_app(self.app_uri)
  File "/usr/local/lib/python3.8/site-packages/gunicorn/util.py", line 359, in import_app
    mod = importlib.import_module(module)
  File "/usr/local/lib/python3.8/importlib/__init__.py", line 127, in import_module
    return _bootstrap._gcd_import(name[level:], package, level)
  File "<frozen importlib._bootstrap>", line 1014, in _gcd_import
  File "<frozen importlib._bootstrap>", line 991, in _find_and_load
  File "<frozen importlib._bootstrap>", line 975, in _find_and_load_unlocked
  File "<frozen importlib._bootstrap>", line 671, in _load_unlocked
  File "<frozen importlib._bootstrap_external>", line 843, in exec_module
  File "<frozen importlib._bootstrap>", line 219, in _call_with_frames_removed
  File "/app/app/__init__.py", line 19, in <module>
    from app import routes
  File "/app/app/routes.py", line 55
    user = User.query.filter_by(email=claims['email').first()
                                                    ^
SyntaxError: closing parenthesis ')' does not match opening parenthesis '['
[2021-08-01 07:34:04 +0000] [9] [ERROR] Exception in worker process
Traceback (most recent call last):
  File "/usr/local/lib/python3.8/site-packages/gunicorn/arbiter.py", line 589, in spawn_worker
    worker.init_process()
  File "/usr/local/lib/python3.8/site-packages/gunicorn/workers/gthread.py", line 92, in init_process
    super().init_process()
  File "/usr/local/lib/python3.8/site-packages/gunicorn/workers/base.py", line 134, in init_process
    self.load_wsgi()
  File "/usr/local/lib/python3.8/site-packages/gunicorn/workers/base.py", line 146, in load_wsgi
    self.wsgi = self.app.wsgi()
  File "/usr/local/lib/python3.8/site-packages/gunicorn/app/base.py", line 67, in wsgi
    self.callable = self.load()
  File "/usr/local/lib/python3.8/site-packages/gunicorn/app/wsgiapp.py", line 58, in load
    return self.load_wsgiapp()
  File "/usr/local/lib/python3.8/site-packages/gunicorn/app/wsgiapp.py", line 48, in load_wsgiapp
    return util.import_app(self.app_uri)
  File "/usr/local/lib/python3.8/site-packages/gunicorn/util.py", line 359, in import_app
    mod = importlib.import_module(module)
  File "/usr/local/lib/python3.8/importlib/__init__.py", line 127, in import_module
    return _bootstrap._gcd_import(name[level:], package, level)
  File "<frozen importlib._bootstrap>", line 1014, in _gcd_import
  File "<frozen importlib._bootstrap>", line 991, in _find_and_load
  File "<frozen importlib._bootstrap>", line 975, in _find_and_load_unlocked
  File "<frozen importlib._bootstrap>", line 671, in _load_unlocked
  File "<frozen importlib._bootstrap_external>", line 843, in exec_module
  File "<frozen importlib._bootstrap>", line 219, in _call_with_frames_removed
  File "/app/app/__init__.py", line 19, in <module>
    from app import routes
  File "/app/app/routes.py", line 55
    user = User.query.filter_by(email=claims['email').first()
                                                    ^
SyntaxError: closing parenthesis ')' does not match opening parenthesis '['
[2021-08-01 07:34:04 +0000] [9] [INFO] Worker exiting (pid: 9)
[2021-08-01 07:34:04 +0000] [10] [INFO] Worker exiting (pid: 10)
[2021-08-01 07:34:07 +0000] [7] [INFO] Starting gunicorn 20.1.0
[2021-08-01 07:34:07 +0000] [7] [INFO] Listening at: http://0.0.0.0:5000 (7)
[2021-08-01 07:34:07 +0000] [7] [INFO] Using worker: gthread
[2021-08-01 07:34:07 +0000] [9] [INFO] Booting worker with pid: 9
[2021-08-01 07:34:07 +0000] [10] [INFO] Booting worker with pid: 10
[2021-08-01 07:34:07 +0000] [9] [ERROR] Exception in worker process
Traceback (most recent call last):
  File "/usr/local/lib/python3.8/site-packages/gunicorn/arbiter.py", line 589, in spawn_worker
    worker.init_process()
  File "/usr/local/lib/python3.8/site-packages/gunicorn/workers/gthread.py", line 92, in init_process
    super().init_process()
  File "/usr/local/lib/python3.8/site-packages/gunicorn/workers/base.py", line 134, in init_process
    self.load_wsgi()
  File "/usr/local/lib/python3.8/site-packages/gunicorn/workers/base.py", line 146, in load_wsgi
    self.wsgi = self.app.wsgi()
  File "/usr/local/lib/python3.8/site-packages/gunicorn/app/base.py", line 67, in wsgi
    self.callable = self.load()
  File "/usr/local/lib/python3.8/site-packages/gunicorn/app/wsgiapp.py", line 58, in load
    return self.load_wsgiapp()
  File "/usr/local/lib/python3.8/site-packages/gunicorn/app/wsgiapp.py", line 48, in load_wsgiapp
    return util.import_app(self.app_uri)
  File "/usr/local/lib/python3.8/site-packages/gunicorn/util.py", line 359, in import_app
    mod = importlib.import_module(module)
  File "/usr/local/lib/python3.8/importlib/__init__.py", line 127, in import_module
    return _bootstrap._gcd_import(name[level:], package, level)
  File "<frozen importlib._bootstrap>", line 1014, in _gcd_import
  File "<frozen importlib._bootstrap>", line 991, in _find_and_load
  File "<frozen importlib._bootstrap>", line 975, in _find_and_load_unlocked
  File "<frozen importlib._bootstrap>", line 671, in _load_unlocked
  File "<frozen importlib._bootstrap_external>", line 843, in exec_module
  File "<frozen importlib._bootstrap>", line 219, in _call_with_frames_removed
  File "/app/app/__init__.py", line 19, in <module>
    from app import routes
  File "/app/app/routes.py", line 55
    user = User.query.filter_by(email=claims['email').first()
                                                    ^
SyntaxError: closing parenthesis ')' does not match opening parenthesis '['
[2021-08-01 07:34:07 +0000] [9] [INFO] Worker exiting (pid: 9)
[2021-08-01 07:34:07 +0000] [10] [ERROR] Exception in worker process
Traceback (most recent call last):
  File "/usr/local/lib/python3.8/site-packages/gunicorn/arbiter.py", line 589, in spawn_worker
    worker.init_process()
  File "/usr/local/lib/python3.8/site-packages/gunicorn/workers/gthread.py", line 92, in init_process
    super().init_process()
  File "/usr/local/lib/python3.8/site-packages/gunicorn/workers/base.py", line 134, in init_process
    self.load_wsgi()
  File "/usr/local/lib/python3.8/site-packages/gunicorn/workers/base.py", line 146, in load_wsgi
    self.wsgi = self.app.wsgi()
  File "/usr/local/lib/python3.8/site-packages/gunicorn/app/base.py", line 67, in wsgi
    self.callable = self.load()
  File "/usr/local/lib/python3.8/site-packages/gunicorn/app/wsgiapp.py", line 58, in load
    return self.load_wsgiapp()
  File "/usr/local/lib/python3.8/site-packages/gunicorn/app/wsgiapp.py", line 48, in load_wsgiapp
    return util.import_app(self.app_uri)
  File "/usr/local/lib/python3.8/site-packages/gunicorn/util.py", line 359, in import_app
    mod = importlib.import_module(module)
  File "/usr/local/lib/python3.8/importlib/__init__.py", line 127, in import_module
    return _bootstrap._gcd_import(name[level:], package, level)
  File "<frozen importlib._bootstrap>", line 1014, in _gcd_import
  File "<frozen importlib._bootstrap>", line 991, in _find_and_load
  File "<frozen importlib._bootstrap>", line 975, in _find_and_load_unlocked
  File "<frozen importlib._bootstrap>", line 671, in _load_unlocked
  File "<frozen importlib._bootstrap_external>", line 843, in exec_module
  File "<frozen importlib._bootstrap>", line 219, in _call_with_frames_removed
  File "/app/app/__init__.py", line 19, in <module>
    from app import routes
  File "/app/app/routes.py", line 55
    user = User.query.filter_by(email=claims['email').first()
                                                    ^
SyntaxError: closing parenthesis ')' does not match opening parenthesis '['
[2021-08-01 07:34:07 +0000] [10] [INFO] Worker exiting (pid: 10)
[2021-08-01 07:34:07 +0000] [7] [WARNING] Worker with pid 10 was terminated due to signal 15
[2021-08-01 07:34:08 +0000] [7] [INFO] Shutting down: Master
[2021-08-01 07:34:08 +0000] [7] [INFO] Reason: Worker failed to boot.
[2021-08-01 07:34:10 +0000] [7] [INFO] Starting gunicorn 20.1.0
[2021-08-01 07:34:10 +0000] [7] [INFO] Listening at: http://0.0.0.0:5000 (7)
[2021-08-01 07:34:10 +0000] [7] [INFO] Using worker: gthread
[2021-08-01 07:34:10 +0000] [9] [INFO] Booting worker with pid: 9
[2021-08-01 07:34:10 +0000] [10] [INFO] Booting worker with pid: 10
[2021-08-01 07:34:10 +0000] [9] [ERROR] Exception in worker process
Traceback (most recent call last):
  File "/usr/local/lib/python3.8/site-packages/gunicorn/arbiter.py", line 589, in spawn_worker
    worker.init_process()
  File "/usr/local/lib/python3.8/site-packages/gunicorn/workers/gthread.py", line 92, in init_process
    super().init_process()
  File "/usr/local/lib/python3.8/site-packages/gunicorn/workers/base.py", line 134, in init_process
    self.load_wsgi()
  File "/usr/local/lib/python3.8/site-packages/gunicorn/workers/base.py", line 146, in load_wsgi
    self.wsgi = self.app.wsgi()
  File "/usr/local/lib/python3.8/site-packages/gunicorn/app/base.py", line 67, in wsgi
    self.callable = self.load()
  File "/usr/local/lib/python3.8/site-packages/gunicorn/app/wsgiapp.py", line 58, in load
    return self.load_wsgiapp()
  File "/usr/local/lib/python3.8/site-packages/gunicorn/app/wsgiapp.py", line 48, in load_wsgiapp
    return util.import_app(self.app_uri)
  File "/usr/local/lib/python3.8/site-packages/gunicorn/util.py", line 359, in import_app
    mod = importlib.import_module(module)
  File "/usr/local/lib/python3.8/importlib/__init__.py", line 127, in import_module
    return _bootstrap._gcd_import(name[level:], package, level)
  File "<frozen importlib._bootstrap>", line 1014, in _gcd_import
  File "<frozen importlib._bootstrap>", line 991, in _find_and_load
  File "<frozen importlib._bootstrap>", line 975, in _find_and_load_unlocked
  File "<frozen importlib._bootstrap>", line 671, in _load_unlocked
  File "<frozen importlib._bootstrap_external>", line 843, in exec_module
  File "<frozen importlib._bootstrap>", line 219, in _call_with_frames_removed
  File "/app/app/__init__.py", line 19, in <module>
    from app import routes
  File "/app/app/routes.py", line 55
    user = User.query.filter_by(email=claims['email').first()
                                                    ^
SyntaxError: closing parenthesis ')' does not match opening parenthesis '['
[2021-08-01 07:34:10 +0000] [10] [ERROR] Exception in worker process
Traceback (most recent call last):
  File "/usr/local/lib/python3.8/site-packages/gunicorn/arbiter.py", line 589, in spawn_worker
    worker.init_process()
  File "/usr/local/lib/python3.8/site-packages/gunicorn/workers/gthread.py", line 92, in init_process
    super().init_process()
  File "/usr/local/lib/python3.8/site-packages/gunicorn/workers/base.py", line 134, in init_process
    self.load_wsgi()
  File "/usr/local/lib/python3.8/site-packages/gunicorn/workers/base.py", line 146, in load_wsgi
    self.wsgi = self.app.wsgi()
  File "/usr/local/lib/python3.8/site-packages/gunicorn/app/base.py", line 67, in wsgi
    self.callable = self.load()
  File "/usr/local/lib/python3.8/site-packages/gunicorn/app/wsgiapp.py", line 58, in load
    return self.load_wsgiapp()
  File "/usr/local/lib/python3.8/site-packages/gunicorn/app/wsgiapp.py", line 48, in load_wsgiapp
    return util.import_app(self.app_uri)
  File "/usr/local/lib/python3.8/site-packages/gunicorn/util.py", line 359, in import_app
    mod = importlib.import_module(module)
  File "/usr/local/lib/python3.8/importlib/__init__.py", line 127, in import_module
    return _bootstrap._gcd_import(name[level:], package, level)
  File "<frozen importlib._bootstrap>", line 1014, in _gcd_import
  File "<frozen importlib._bootstrap>", line 991, in _find_and_load
  File "<frozen importlib._bootstrap>", line 975, in _find_and_load_unlocked
  File "<frozen importlib._bootstrap>", line 671, in _load_unlocked
  File "<frozen importlib._bootstrap_external>", line 843, in exec_module
  File "<frozen importlib._bootstrap>", line 219, in _call_with_frames_removed
  File "/app/app/__init__.py", line 19, in <module>
    from app import routes
  File "/app/app/routes.py", line 55
    user = User.query.filter_by(email=claims['email').first()
                                                    ^
SyntaxError: closing parenthesis ')' does not match opening parenthesis '['
[2021-08-01 07:34:10 +0000] [10] [INFO] Worker exiting (pid: 10)
[2021-08-01 07:34:10 +0000] [9] [INFO] Worker exiting (pid: 9)
[2021-08-01 07:34:13 +0000] [7] [INFO] Starting gunicorn 20.1.0
[2021-08-01 07:34:13 +0000] [7] [INFO] Listening at: http://0.0.0.0:5000 (7)
[2021-08-01 07:34:13 +0000] [7] [INFO] Using worker: gthread
[2021-08-01 07:34:13 +0000] [9] [INFO] Booting worker with pid: 9
[2021-08-01 07:34:13 +0000] [10] [INFO] Booting worker with pid: 10
[2021-08-01 07:34:14 +0000] [9] [ERROR] Exception in worker process
Traceback (most recent call last):
  File "/usr/local/lib/python3.8/site-packages/gunicorn/arbiter.py", line 589, in spawn_worker
    worker.init_process()
  File "/usr/local/lib/python3.8/site-packages/gunicorn/workers/gthread.py", line 92, in init_process
    super().init_process()
  File "/usr/local/lib/python3.8/site-packages/gunicorn/workers/base.py", line 134, in init_process
    self.load_wsgi()
  File "/usr/local/lib/python3.8/site-packages/gunicorn/workers/base.py", line 146, in load_wsgi
    self.wsgi = self.app.wsgi()
  File "/usr/local/lib/python3.8/site-packages/gunicorn/app/base.py", line 67, in wsgi
    self.callable = self.load()
  File "/usr/local/lib/python3.8/site-packages/gunicorn/app/wsgiapp.py", line 58, in load
    return self.load_wsgiapp()
  File "/usr/local/lib/python3.8/site-packages/gunicorn/app/wsgiapp.py", line 48, in load_wsgiapp
    return util.import_app(self.app_uri)
  File "/usr/local/lib/python3.8/site-packages/gunicorn/util.py", line 359, in import_app
    mod = importlib.import_module(module)
  File "/usr/local/lib/python3.8/importlib/__init__.py", line 127, in import_module
    return _bootstrap._gcd_import(name[level:], package, level)
  File "<frozen importlib._bootstrap>", line 1014, in _gcd_import
  File "<frozen importlib._bootstrap>", line 991, in _find_and_load
  File "<frozen importlib._bootstrap>", line 975, in _find_and_load_unlocked
  File "<frozen importlib._bootstrap>", line 671, in _load_unlocked
  File "<frozen importlib._bootstrap_external>", line 843, in exec_module
  File "<frozen importlib._bootstrap>", line 219, in _call_with_frames_removed
  File "/app/app/__init__.py", line 19, in <module>
    from app import routes
  File "/app/app/routes.py", line 55
    user = User.query.filter_by(email=claims['email').first()
                                                    ^
SyntaxError: closing parenthesis ')' does not match opening parenthesis '['
[2021-08-01 07:34:14 +0000] [9] [INFO] Worker exiting (pid: 9)
[2021-08-01 07:34:14 +0000] [10] [ERROR] Exception in worker process
Traceback (most recent call last):
  File "/usr/local/lib/python3.8/site-packages/gunicorn/arbiter.py", line 589, in spawn_worker
    worker.init_process()
  File "/usr/local/lib/python3.8/site-packages/gunicorn/workers/gthread.py", line 92, in init_process
    super().init_process()
  File "/usr/local/lib/python3.8/site-packages/gunicorn/workers/base.py", line 134, in init_process
    self.load_wsgi()
  File "/usr/local/lib/python3.8/site-packages/gunicorn/workers/base.py", line 146, in load_wsgi
    self.wsgi = self.app.wsgi()
  File "/usr/local/lib/python3.8/site-packages/gunicorn/app/base.py", line 67, in wsgi
    self.callable = self.load()
  File "/usr/local/lib/python3.8/site-packages/gunicorn/app/wsgiapp.py", line 58, in load
    return self.load_wsgiapp()
  File "/usr/local/lib/python3.8/site-packages/gunicorn/app/wsgiapp.py", line 48, in load_wsgiapp
    return util.import_app(self.app_uri)
  File "/usr/local/lib/python3.8/site-packages/gunicorn/util.py", line 359, in import_app
    mod = importlib.import_module(module)
  File "/usr/local/lib/python3.8/importlib/__init__.py", line 127, in import_module
    return _bootstrap._gcd_import(name[level:], package, level)
  File "<frozen importlib._bootstrap>", line 1014, in _gcd_import
  File "<frozen importlib._bootstrap>", line 991, in _find_and_load
  File "<frozen importlib._bootstrap>", line 975, in _find_and_load_unlocked
  File "<frozen importlib._bootstrap>", line 671, in _load_unlocked
  File "<frozen importlib._bootstrap_external>", line 843, in exec_module
  File "<frozen importlib._bootstrap>", line 219, in _call_with_frames_removed
  File "/app/app/__init__.py", line 19, in <module>
    from app import routes
  File "/app/app/routes.py", line 55
    user = User.query.filter_by(email=claims['email').first()
                                                    ^
SyntaxError: closing parenthesis ')' does not match opening parenthesis '['
[2021-08-01 07:34:14 +0000] [10] [INFO] Worker exiting (pid: 10)
[2021-08-01 07:34:14 +0000] [7] [WARNING] Worker with pid 10 was terminated due to signal 15
[2021-08-01 07:34:14 +0000] [7] [INFO] Shutting down: Master
[2021-08-01 07:34:14 +0000] [7] [INFO] Reason: Worker failed to boot.
[2021-08-01 07:34:16 +0000] [8] [INFO] Starting gunicorn 20.1.0
[2021-08-01 07:34:16 +0000] [8] [INFO] Listening at: http://0.0.0.0:5000 (8)
[2021-08-01 07:34:16 +0000] [8] [INFO] Using worker: gthread
[2021-08-01 07:34:17 +0000] [10] [INFO] Booting worker with pid: 10
[2021-08-01 07:34:17 +0000] [11] [INFO] Booting worker with pid: 11
[2021-08-01 07:34:17 +0000] [10] [ERROR] Exception in worker process
Traceback (most recent call last):
  File "/usr/local/lib/python3.8/site-packages/gunicorn/arbiter.py", line 589, in spawn_worker
    worker.init_process()
  File "/usr/local/lib/python3.8/site-packages/gunicorn/workers/gthread.py", line 92, in init_process
    super().init_process()
  File "/usr/local/lib/python3.8/site-packages/gunicorn/workers/base.py", line 134, in init_process
    self.load_wsgi()
  File "/usr/local/lib/python3.8/site-packages/gunicorn/workers/base.py", line 146, in load_wsgi
    self.wsgi = self.app.wsgi()
  File "/usr/local/lib/python3.8/site-packages/gunicorn/app/base.py", line 67, in wsgi
    self.callable = self.load()
  File "/usr/local/lib/python3.8/site-packages/gunicorn/app/wsgiapp.py", line 58, in load
    return self.load_wsgiapp()
  File "/usr/local/lib/python3.8/site-packages/gunicorn/app/wsgiapp.py", line 48, in load_wsgiapp
    return util.import_app(self.app_uri)
  File "/usr/local/lib/python3.8/site-packages/gunicorn/util.py", line 359, in import_app
    mod = importlib.import_module(module)
  File "/usr/local/lib/python3.8/importlib/__init__.py", line 127, in import_module
    return _bootstrap._gcd_import(name[level:], package, level)
  File "<frozen importlib._bootstrap>", line 1014, in _gcd_import
  File "<frozen importlib._bootstrap>", line 991, in _find_and_load
  File "<frozen importlib._bootstrap>", line 975, in _find_and_load_unlocked
  File "<frozen importlib._bootstrap>", line 671, in _load_unlocked
  File "<frozen importlib._bootstrap_external>", line 843, in exec_module
  File "<frozen importlib._bootstrap>", line 219, in _call_with_frames_removed
  File "/app/app/__init__.py", line 19, in <module>
    from app import routes
  File "/app/app/routes.py", line 55
    user = User.query.filter_by(email=claims['email').first()
                                                    ^
SyntaxError: closing parenthesis ')' does not match opening parenthesis '['
[2021-08-01 07:34:17 +0000] [10] [INFO] Worker exiting (pid: 10)
[2021-08-01 07:34:17 +0000] [11] [ERROR] Exception in worker process
Traceback (most recent call last):
  File "/usr/local/lib/python3.8/site-packages/gunicorn/arbiter.py", line 589, in spawn_worker
    worker.init_process()
  File "/usr/local/lib/python3.8/site-packages/gunicorn/workers/gthread.py", line 92, in init_process
    super().init_process()
  File "/usr/local/lib/python3.8/site-packages/gunicorn/workers/base.py", line 134, in init_process
    self.load_wsgi()
  File "/usr/local/lib/python3.8/site-packages/gunicorn/workers/base.py", line 146, in load_wsgi
    self.wsgi = self.app.wsgi()
  File "/usr/local/lib/python3.8/site-packages/gunicorn/app/base.py", line 67, in wsgi
    self.callable = self.load()
  File "/usr/local/lib/python3.8/site-packages/gunicorn/app/wsgiapp.py", line 58, in load
    return self.load_wsgiapp()
  File "/usr/local/lib/python3.8/site-packages/gunicorn/app/wsgiapp.py", line 48, in load_wsgiapp
    return util.import_app(self.app_uri)
  File "/usr/local/lib/python3.8/site-packages/gunicorn/util.py", line 359, in import_app
    mod = importlib.import_module(module)
  File "/usr/local/lib/python3.8/importlib/__init__.py", line 127, in import_module
    return _bootstrap._gcd_import(name[level:], package, level)
  File "<frozen importlib._bootstrap>", line 1014, in _gcd_import
  File "<frozen importlib._bootstrap>", line 991, in _find_and_load
  File "<frozen importlib._bootstrap>", line 975, in _find_and_load_unlocked
  File "<frozen importlib._bootstrap>", line 671, in _load_unlocked
  File "<frozen importlib._bootstrap_external>", line 843, in exec_module
  File "<frozen importlib._bootstrap>", line 219, in _call_with_frames_removed
  File "/app/app/__init__.py", line 19, in <module>
    from app import routes
  File "/app/app/routes.py", line 55
    user = User.query.filter_by(email=claims['email').first()
                                                    ^
SyntaxError: closing parenthesis ')' does not match opening parenthesis '['
[2021-08-01 07:34:17 +0000] [11] [INFO] Worker exiting (pid: 11)
[2021-08-01 07:34:20 +0000] [7] [INFO] Starting gunicorn 20.1.0
[2021-08-01 07:34:20 +0000] [7] [INFO] Listening at: http://0.0.0.0:5000 (7)
[2021-08-01 07:34:20 +0000] [7] [INFO] Using worker: gthread
[2021-08-01 07:34:20 +0000] [9] [INFO] Booting worker with pid: 9
[2021-08-01 07:34:20 +0000] [10] [INFO] Booting worker with pid: 10
[2021-08-01 07:34:21 +0000] [9] [ERROR] Exception in worker process
Traceback (most recent call last):
  File "/usr/local/lib/python3.8/site-packages/gunicorn/arbiter.py", line 589, in spawn_worker
    worker.init_process()
  File "/usr/local/lib/python3.8/site-packages/gunicorn/workers/gthread.py", line 92, in init_process
    super().init_process()
  File "/usr/local/lib/python3.8/site-packages/gunicorn/workers/base.py", line 134, in init_process
    self.load_wsgi()
  File "/usr/local/lib/python3.8/site-packages/gunicorn/workers/base.py", line 146, in load_wsgi
    self.wsgi = self.app.wsgi()
  File "/usr/local/lib/python3.8/site-packages/gunicorn/app/base.py", line 67, in wsgi
    self.callable = self.load()
  File "/usr/local/lib/python3.8/site-packages/gunicorn/app/wsgiapp.py", line 58, in load
    return self.load_wsgiapp()
  File "/usr/local/lib/python3.8/site-packages/gunicorn/app/wsgiapp.py", line 48, in load_wsgiapp
    return util.import_app(self.app_uri)
  File "/usr/local/lib/python3.8/site-packages/gunicorn/util.py", line 359, in import_app
    mod = importlib.import_module(module)
  File "/usr/local/lib/python3.8/importlib/__init__.py", line 127, in import_module
    return _bootstrap._gcd_import(name[level:], package, level)
  File "<frozen importlib._bootstrap>", line 1014, in _gcd_import
  File "<frozen importlib._bootstrap>", line 991, in _find_and_load
  File "<frozen importlib._bootstrap>", line 975, in _find_and_load_unlocked
  File "<frozen importlib._bootstrap>", line 671, in _load_unlocked
  File "<frozen importlib._bootstrap_external>", line 843, in exec_module
  File "<frozen importlib._bootstrap>", line 219, in _call_with_frames_removed
  File "/app/app/__init__.py", line 19, in <module>
    from app import routes
  File "/app/app/routes.py", line 55
    user = User.query.filter_by(email=claims['email').first()
                                                    ^
SyntaxError: closing parenthesis ')' does not match opening parenthesis '['
[2021-08-01 07:34:21 +0000] [9] [INFO] Worker exiting (pid: 9)
[2021-08-01 07:34:21 +0000] [10] [ERROR] Exception in worker process
Traceback (most recent call last):
  File "/usr/local/lib/python3.8/site-packages/gunicorn/arbiter.py", line 589, in spawn_worker
    worker.init_process()
  File "/usr/local/lib/python3.8/site-packages/gunicorn/workers/gthread.py", line 92, in init_process
    super().init_process()
  File "/usr/local/lib/python3.8/site-packages/gunicorn/workers/base.py", line 134, in init_process
    self.load_wsgi()
  File "/usr/local/lib/python3.8/site-packages/gunicorn/workers/base.py", line 146, in load_wsgi
    self.wsgi = self.app.wsgi()
  File "/usr/local/lib/python3.8/site-packages/gunicorn/app/base.py", line 67, in wsgi
    self.callable = self.load()
  File "/usr/local/lib/python3.8/site-packages/gunicorn/app/wsgiapp.py", line 58, in load
    return self.load_wsgiapp()
  File "/usr/local/lib/python3.8/site-packages/gunicorn/app/wsgiapp.py", line 48, in load_wsgiapp
    return util.import_app(self.app_uri)
  File "/usr/local/lib/python3.8/site-packages/gunicorn/util.py", line 359, in import_app
    mod = importlib.import_module(module)
  File "/usr/local/lib/python3.8/importlib/__init__.py", line 127, in import_module
    return _bootstrap._gcd_import(name[level:], package, level)
  File "<frozen importlib._bootstrap>", line 1014, in _gcd_import
  File "<frozen importlib._bootstrap>", line 991, in _find_and_load
  File "<frozen importlib._bootstrap>", line 975, in _find_and_load_unlocked
  File "<frozen importlib._bootstrap>", line 671, in _load_unlocked
  File "<frozen importlib._bootstrap_external>", line 843, in exec_module
  File "<frozen importlib._bootstrap>", line 219, in _call_with_frames_removed
  File "/app/app/__init__.py", line 19, in <module>
    from app import routes
  File "/app/app/routes.py", line 55
    user = User.query.filter_by(email=claims['email').first()
                                                    ^
SyntaxError: closing parenthesis ')' does not match opening parenthesis '['
[2021-08-01 07:34:21 +0000] [10] [INFO] Worker exiting (pid: 10)
[2021-08-01 07:34:21 +0000] [7] [WARNING] Worker with pid 10 was terminated due to signal 15
[2021-08-01 07:34:21 +0000] [7] [INFO] Shutting down: Master
[2021-08-01 07:34:21 +0000] [7] [INFO] Reason: Worker failed to boot.
[2021-08-01 07:34:26 +0000] [7] [INFO] Starting gunicorn 20.1.0
[2021-08-01 07:34:26 +0000] [7] [INFO] Listening at: http://0.0.0.0:5000 (7)
[2021-08-01 07:34:26 +0000] [7] [INFO] Using worker: gthread
[2021-08-01 07:34:26 +0000] [9] [INFO] Booting worker with pid: 9
[2021-08-01 07:34:26 +0000] [10] [INFO] Booting worker with pid: 10
[2021-08-01 07:34:26 +0000] [9] [ERROR] Exception in worker process
Traceback (most recent call last):
  File "/usr/local/lib/python3.8/site-packages/gunicorn/arbiter.py", line 589, in spawn_worker
    worker.init_process()
  File "/usr/local/lib/python3.8/site-packages/gunicorn/workers/gthread.py", line 92, in init_process
    super().init_process()
  File "/usr/local/lib/python3.8/site-packages/gunicorn/workers/base.py", line 134, in init_process
    self.load_wsgi()
  File "/usr/local/lib/python3.8/site-packages/gunicorn/workers/base.py", line 146, in load_wsgi
    self.wsgi = self.app.wsgi()
  File "/usr/local/lib/python3.8/site-packages/gunicorn/app/base.py", line 67, in wsgi
    self.callable = self.load()
  File "/usr/local/lib/python3.8/site-packages/gunicorn/app/wsgiapp.py", line 58, in load
    return self.load_wsgiapp()
  File "/usr/local/lib/python3.8/site-packages/gunicorn/app/wsgiapp.py", line 48, in load_wsgiapp
    return util.import_app(self.app_uri)
  File "/usr/local/lib/python3.8/site-packages/gunicorn/util.py", line 359, in import_app
    mod = importlib.import_module(module)
  File "/usr/local/lib/python3.8/importlib/__init__.py", line 127, in import_module
    return _bootstrap._gcd_import(name[level:], package, level)
  File "<frozen importlib._bootstrap>", line 1014, in _gcd_import
  File "<frozen importlib._bootstrap>", line 991, in _find_and_load
  File "<frozen importlib._bootstrap>", line 975, in _find_and_load_unlocked
  File "<frozen importlib._bootstrap>", line 671, in _load_unlocked
  File "<frozen importlib._bootstrap_external>", line 843, in exec_module
  File "<frozen importlib._bootstrap>", line 219, in _call_with_frames_removed
  File "/app/app/__init__.py", line 19, in <module>
    from app import routes
  File "/app/app/routes.py", line 55
    user = User.query.filter_by(email=claims['email').first()
                                                    ^
SyntaxError: closing parenthesis ')' does not match opening parenthesis '['
[2021-08-01 07:34:26 +0000] [10] [ERROR] Exception in worker process
Traceback (most recent call last):
  File "/usr/local/lib/python3.8/site-packages/gunicorn/arbiter.py", line 589, in spawn_worker
    worker.init_process()
  File "/usr/local/lib/python3.8/site-packages/gunicorn/workers/gthread.py", line 92, in init_process
    super().init_process()
  File "/usr/local/lib/python3.8/site-packages/gunicorn/workers/base.py", line 134, in init_process
    self.load_wsgi()
  File "/usr/local/lib/python3.8/site-packages/gunicorn/workers/base.py", line 146, in load_wsgi
    self.wsgi = self.app.wsgi()
  File "/usr/local/lib/python3.8/site-packages/gunicorn/app/base.py", line 67, in wsgi
    self.callable = self.load()
  File "/usr/local/lib/python3.8/site-packages/gunicorn/app/wsgiapp.py", line 58, in load
    return self.load_wsgiapp()
  File "/usr/local/lib/python3.8/site-packages/gunicorn/app/wsgiapp.py", line 48, in load_wsgiapp
    return util.import_app(self.app_uri)
  File "/usr/local/lib/python3.8/site-packages/gunicorn/util.py", line 359, in import_app
    mod = importlib.import_module(module)
  File "/usr/local/lib/python3.8/importlib/__init__.py", line 127, in import_module
    return _bootstrap._gcd_import(name[level:], package, level)
  File "<frozen importlib._bootstrap>", line 1014, in _gcd_import
  File "<frozen importlib._bootstrap>", line 991, in _find_and_load
  File "<frozen importlib._bootstrap>", line 975, in _find_and_load_unlocked
  File "<frozen importlib._bootstrap>", line 671, in _load_unlocked
  File "<frozen importlib._bootstrap_external>", line 843, in exec_module
  File "<frozen importlib._bootstrap>", line 219, in _call_with_frames_removed
  File "/app/app/__init__.py", line 19, in <module>
    from app import routes
  File "/app/app/routes.py", line 55
    user = User.query.filter_by(email=claims['email').first()
                                                    ^
SyntaxError: closing parenthesis ')' does not match opening parenthesis '['
[2021-08-01 07:34:26 +0000] [9] [INFO] Worker exiting (pid: 9)
[2021-08-01 07:34:26 +0000] [10] [INFO] Worker exiting (pid: 10)
[2021-08-01 07:34:34 +0000] [7] [INFO] Starting gunicorn 20.1.0
[2021-08-01 07:34:34 +0000] [7] [INFO] Listening at: http://0.0.0.0:5000 (7)
[2021-08-01 07:34:34 +0000] [7] [INFO] Using worker: gthread
[2021-08-01 07:34:34 +0000] [9] [INFO] Booting worker with pid: 9
[2021-08-01 07:34:34 +0000] [10] [INFO] Booting worker with pid: 10
[2021-08-01 07:34:35 +0000] [9] [ERROR] Exception in worker process
Traceback (most recent call last):
  File "/usr/local/lib/python3.8/site-packages/gunicorn/arbiter.py", line 589, in spawn_worker
    worker.init_process()
  File "/usr/local/lib/python3.8/site-packages/gunicorn/workers/gthread.py", line 92, in init_process
    super().init_process()
  File "/usr/local/lib/python3.8/site-packages/gunicorn/workers/base.py", line 134, in init_process
    self.load_wsgi()
  File "/usr/local/lib/python3.8/site-packages/gunicorn/workers/base.py", line 146, in load_wsgi
    self.wsgi = self.app.wsgi()
  File "/usr/local/lib/python3.8/site-packages/gunicorn/app/base.py", line 67, in wsgi
    self.callable = self.load()
  File "/usr/local/lib/python3.8/site-packages/gunicorn/app/wsgiapp.py", line 58, in load
    return self.load_wsgiapp()
  File "/usr/local/lib/python3.8/site-packages/gunicorn/app/wsgiapp.py", line 48, in load_wsgiapp
    return util.import_app(self.app_uri)
  File "/usr/local/lib/python3.8/site-packages/gunicorn/util.py", line 359, in import_app
    mod = importlib.import_module(module)
  File "/usr/local/lib/python3.8/importlib/__init__.py", line 127, in import_module
    return _bootstrap._gcd_import(name[level:], package, level)
  File "<frozen importlib._bootstrap>", line 1014, in _gcd_import
  File "<frozen importlib._bootstrap>", line 991, in _find_and_load
  File "<frozen importlib._bootstrap>", line 975, in _find_and_load_unlocked
  File "<frozen importlib._bootstrap>", line 671, in _load_unlocked
  File "<frozen importlib._bootstrap_external>", line 843, in exec_module
  File "<frozen importlib._bootstrap>", line 219, in _call_with_frames_removed
  File "/app/app/__init__.py", line 19, in <module>
    from app import routes
  File "/app/app/routes.py", line 55
    user = User.query.filter_by(email=claims['email').first()
                                                    ^
SyntaxError: closing parenthesis ')' does not match opening parenthesis '['
[2021-08-01 07:34:35 +0000] [9] [INFO] Worker exiting (pid: 9)
[2021-08-01 07:34:35 +0000] [10] [ERROR] Exception in worker process
Traceback (most recent call last):
  File "/usr/local/lib/python3.8/site-packages/gunicorn/arbiter.py", line 589, in spawn_worker
    worker.init_process()
  File "/usr/local/lib/python3.8/site-packages/gunicorn/workers/gthread.py", line 92, in init_process
    super().init_process()
  File "/usr/local/lib/python3.8/site-packages/gunicorn/workers/base.py", line 134, in init_process
    self.load_wsgi()
  File "/usr/local/lib/python3.8/site-packages/gunicorn/workers/base.py", line 146, in load_wsgi
    self.wsgi = self.app.wsgi()
  File "/usr/local/lib/python3.8/site-packages/gunicorn/app/base.py", line 67, in wsgi
    self.callable = self.load()
  File "/usr/local/lib/python3.8/site-packages/gunicorn/app/wsgiapp.py", line 58, in load
    return self.load_wsgiapp()
  File "/usr/local/lib/python3.8/site-packages/gunicorn/app/wsgiapp.py", line 48, in load_wsgiapp
    return util.import_app(self.app_uri)
  File "/usr/local/lib/python3.8/site-packages/gunicorn/util.py", line 359, in import_app
    mod = importlib.import_module(module)
  File "/usr/local/lib/python3.8/importlib/__init__.py", line 127, in import_module
    return _bootstrap._gcd_import(name[level:], package, level)
  File "<frozen importlib._bootstrap>", line 1014, in _gcd_import
  File "<frozen importlib._bootstrap>", line 991, in _find_and_load
  File "<frozen importlib._bootstrap>", line 975, in _find_and_load_unlocked
  File "<frozen importlib._bootstrap>", line 671, in _load_unlocked
  File "<frozen importlib._bootstrap_external>", line 843, in exec_module
  File "<frozen importlib._bootstrap>", line 219, in _call_with_frames_removed
  File "/app/app/__init__.py", line 19, in <module>
    from app import routes
  File "/app/app/routes.py", line 55
    user = User.query.filter_by(email=claims['email').first()
                                                    ^
SyntaxError: closing parenthesis ')' does not match opening parenthesis '['
[2021-08-01 07:34:35 +0000] [10] [INFO] Worker exiting (pid: 10)
[2021-08-01 07:34:49 +0000] [7] [INFO] Starting gunicorn 20.1.0
[2021-08-01 07:34:49 +0000] [7] [INFO] Listening at: http://0.0.0.0:5000 (7)
[2021-08-01 07:34:49 +0000] [7] [INFO] Using worker: gthread
[2021-08-01 07:34:49 +0000] [9] [INFO] Booting worker with pid: 9
[2021-08-01 07:34:49 +0000] [10] [INFO] Booting worker with pid: 10
[2021-08-01 07:34:49 +0000] [9] [ERROR] Exception in worker process
Traceback (most recent call last):
  File "/usr/local/lib/python3.8/site-packages/gunicorn/arbiter.py", line 589, in spawn_worker
    worker.init_process()
  File "/usr/local/lib/python3.8/site-packages/gunicorn/workers/gthread.py", line 92, in init_process
    super().init_process()
  File "/usr/local/lib/python3.8/site-packages/gunicorn/workers/base.py", line 134, in init_process
    self.load_wsgi()
  File "/usr/local/lib/python3.8/site-packages/gunicorn/workers/base.py", line 146, in load_wsgi
    self.wsgi = self.app.wsgi()
  File "/usr/local/lib/python3.8/site-packages/gunicorn/app/base.py", line 67, in wsgi
    self.callable = self.load()
  File "/usr/local/lib/python3.8/site-packages/gunicorn/app/wsgiapp.py", line 58, in load
    return self.load_wsgiapp()
  File "/usr/local/lib/python3.8/site-packages/gunicorn/app/wsgiapp.py", line 48, in load_wsgiapp
    return util.import_app(self.app_uri)
  File "/usr/local/lib/python3.8/site-packages/gunicorn/util.py", line 359, in import_app
    mod = importlib.import_module(module)
  File "/usr/local/lib/python3.8/importlib/__init__.py", line 127, in import_module
    return _bootstrap._gcd_import(name[level:], package, level)
  File "<frozen importlib._bootstrap>", line 1014, in _gcd_import
  File "<frozen importlib._bootstrap>", line 991, in _find_and_load
  File "<frozen importlib._bootstrap>", line 975, in _find_and_load_unlocked
  File "<frozen importlib._bootstrap>", line 671, in _load_unlocked
  File "<frozen importlib._bootstrap_external>", line 843, in exec_module
  File "<frozen importlib._bootstrap>", line 219, in _call_with_frames_removed
  File "/app/app/__init__.py", line 19, in <module>
    from app import routes
  File "/app/app/routes.py", line 55
    user = User.query.filter_by(email=claims['email').first()
                                                    ^
SyntaxError: closing parenthesis ')' does not match opening parenthesis '['
[2021-08-01 07:34:49 +0000] [9] [INFO] Worker exiting (pid: 9)
[2021-08-01 07:34:50 +0000] [10] [ERROR] Exception in worker process
Traceback (most recent call last):
  File "/usr/local/lib/python3.8/site-packages/gunicorn/arbiter.py", line 589, in spawn_worker
    worker.init_process()
  File "/usr/local/lib/python3.8/site-packages/gunicorn/workers/gthread.py", line 92, in init_process
    super().init_process()
  File "/usr/local/lib/python3.8/site-packages/gunicorn/workers/base.py", line 134, in init_process
    self.load_wsgi()
  File "/usr/local/lib/python3.8/site-packages/gunicorn/workers/base.py", line 146, in load_wsgi
    self.wsgi = self.app.wsgi()
  File "/usr/local/lib/python3.8/site-packages/gunicorn/app/base.py", line 67, in wsgi
    self.callable = self.load()
  File "/usr/local/lib/python3.8/site-packages/gunicorn/app/wsgiapp.py", line 58, in load
    return self.load_wsgiapp()
  File "/usr/local/lib/python3.8/site-packages/gunicorn/app/wsgiapp.py", line 48, in load_wsgiapp
    return util.import_app(self.app_uri)
  File "/usr/local/lib/python3.8/site-packages/gunicorn/util.py", line 359, in import_app
    mod = importlib.import_module(module)
  File "/usr/local/lib/python3.8/importlib/__init__.py", line 127, in import_module
    return _bootstrap._gcd_import(name[level:], package, level)
  File "<frozen importlib._bootstrap>", line 1014, in _gcd_import
  File "<frozen importlib._bootstrap>", line 991, in _find_and_load
  File "<frozen importlib._bootstrap>", line 975, in _find_and_load_unlocked
  File "<frozen importlib._bootstrap>", line 671, in _load_unlocked
  File "<frozen importlib._bootstrap_external>", line 843, in exec_module
  File "<frozen importlib._bootstrap>", line 219, in _call_with_frames_removed
  File "/app/app/__init__.py", line 19, in <module>
    from app import routes
  File "/app/app/routes.py", line 55
    user = User.query.filter_by(email=claims['email').first()
                                                    ^
SyntaxError: closing parenthesis ')' does not match opening parenthesis '['
[2021-08-01 07:34:50 +0000] [10] [INFO] Worker exiting (pid: 10)
[2021-08-01 07:35:17 +0000] [8] [INFO] Starting gunicorn 20.1.0
[2021-08-01 07:35:17 +0000] [8] [INFO] Listening at: http://0.0.0.0:5000 (8)
[2021-08-01 07:35:17 +0000] [8] [INFO] Using worker: gthread
[2021-08-01 07:35:17 +0000] [10] [INFO] Booting worker with pid: 10
[2021-08-01 07:35:17 +0000] [11] [INFO] Booting worker with pid: 11
[2021-08-01 07:35:17 +0000] [10] [ERROR] Exception in worker process
Traceback (most recent call last):
  File "/usr/local/lib/python3.8/site-packages/gunicorn/arbiter.py", line 589, in spawn_worker
    worker.init_process()
  File "/usr/local/lib/python3.8/site-packages/gunicorn/workers/gthread.py", line 92, in init_process
    super().init_process()
  File "/usr/local/lib/python3.8/site-packages/gunicorn/workers/base.py", line 134, in init_process
    self.load_wsgi()
  File "/usr/local/lib/python3.8/site-packages/gunicorn/workers/base.py", line 146, in load_wsgi
    self.wsgi = self.app.wsgi()
  File "/usr/local/lib/python3.8/site-packages/gunicorn/app/base.py", line 67, in wsgi
    self.callable = self.load()
  File "/usr/local/lib/python3.8/site-packages/gunicorn/app/wsgiapp.py", line 58, in load
    return self.load_wsgiapp()
  File "/usr/local/lib/python3.8/site-packages/gunicorn/app/wsgiapp.py", line 48, in load_wsgiapp
    return util.import_app(self.app_uri)
  File "/usr/local/lib/python3.8/site-packages/gunicorn/util.py", line 359, in import_app
    mod = importlib.import_module(module)
  File "/usr/local/lib/python3.8/importlib/__init__.py", line 127, in import_module
    return _bootstrap._gcd_import(name[level:], package, level)
  File "<frozen importlib._bootstrap>", line 1014, in _gcd_import
  File "<frozen importlib._bootstrap>", line 991, in _find_and_load
  File "<frozen importlib._bootstrap>", line 975, in _find_and_load_unlocked
  File "<frozen importlib._bootstrap>", line 671, in _load_unlocked
  File "<frozen importlib._bootstrap_external>", line 843, in exec_module
  File "<frozen importlib._bootstrap>", line 219, in _call_with_frames_removed
  File "/app/app/__init__.py", line 19, in <module>
    from app import routes
  File "/app/app/routes.py", line 55
    user = User.query.filter_by(email=claims['email').first()
                                                    ^
SyntaxError: closing parenthesis ')' does not match opening parenthesis '['
[2021-08-01 07:35:17 +0000] [10] [INFO] Worker exiting (pid: 10)
[2021-08-01 07:35:17 +0000] [11] [ERROR] Exception in worker process
Traceback (most recent call last):
  File "/usr/local/lib/python3.8/site-packages/gunicorn/arbiter.py", line 589, in spawn_worker
    worker.init_process()
  File "/usr/local/lib/python3.8/site-packages/gunicorn/workers/gthread.py", line 92, in init_process
    super().init_process()
  File "/usr/local/lib/python3.8/site-packages/gunicorn/workers/base.py", line 134, in init_process
    self.load_wsgi()
  File "/usr/local/lib/python3.8/site-packages/gunicorn/workers/base.py", line 146, in load_wsgi
    self.wsgi = self.app.wsgi()
  File "/usr/local/lib/python3.8/site-packages/gunicorn/app/base.py", line 67, in wsgi
    self.callable = self.load()
  File "/usr/local/lib/python3.8/site-packages/gunicorn/app/wsgiapp.py", line 58, in load
    return self.load_wsgiapp()
  File "/usr/local/lib/python3.8/site-packages/gunicorn/app/wsgiapp.py", line 48, in load_wsgiapp
    return util.import_app(self.app_uri)
  File "/usr/local/lib/python3.8/site-packages/gunicorn/util.py", line 359, in import_app
    mod = importlib.import_module(module)
  File "/usr/local/lib/python3.8/importlib/__init__.py", line 127, in import_module
    return _bootstrap._gcd_import(name[level:], package, level)
  File "<frozen importlib._bootstrap>", line 1014, in _gcd_import
  File "<frozen importlib._bootstrap>", line 991, in _find_and_load
  File "<frozen importlib._bootstrap>", line 975, in _find_and_load_unlocked
  File "<frozen importlib._bootstrap>", line 671, in _load_unlocked
  File "<frozen importlib._bootstrap_external>", line 843, in exec_module
  File "<frozen importlib._bootstrap>", line 219, in _call_with_frames_removed
  File "/app/app/__init__.py", line 19, in <module>
    from app import routes
  File "/app/app/routes.py", line 55
    user = User.query.filter_by(email=claims['email').first()
                                                    ^
SyntaxError: closing parenthesis ')' does not match opening parenthesis '['
[2021-08-01 07:35:17 +0000] [11] [INFO] Worker exiting (pid: 11)
[2021-08-01 07:35:17 +0000] [8] [WARNING] Worker with pid 11 was terminated due to signal 15
[2021-08-01 07:35:17 +0000] [8] [INFO] Shutting down: Master
[2021-08-01 07:35:17 +0000] [8] [INFO] Reason: Worker failed to boot.
[2021-08-01 07:36:04 +0000] [7] [INFO] Starting gunicorn 20.1.0
[2021-08-01 07:36:04 +0000] [7] [INFO] Listening at: http://0.0.0.0:5000 (7)
[2021-08-01 07:36:04 +0000] [7] [INFO] Using worker: gthread
[2021-08-01 07:36:04 +0000] [9] [INFO] Booting worker with pid: 9
[2021-08-01 07:36:04 +0000] [10] [INFO] Booting worker with pid: 10
[2021-08-01 07:36:05 +0000] [10] [ERROR] Exception in worker process
Traceback (most recent call last):
  File "/usr/local/lib/python3.8/site-packages/gunicorn/arbiter.py", line 589, in spawn_worker
    worker.init_process()
  File "/usr/local/lib/python3.8/site-packages/gunicorn/workers/gthread.py", line 92, in init_process
    super().init_process()
  File "/usr/local/lib/python3.8/site-packages/gunicorn/workers/base.py", line 134, in init_process
    self.load_wsgi()
  File "/usr/local/lib/python3.8/site-packages/gunicorn/workers/base.py", line 146, in load_wsgi
    self.wsgi = self.app.wsgi()
  File "/usr/local/lib/python3.8/site-packages/gunicorn/app/base.py", line 67, in wsgi
    self.callable = self.load()
  File "/usr/local/lib/python3.8/site-packages/gunicorn/app/wsgiapp.py", line 58, in load
    return self.load_wsgiapp()
  File "/usr/local/lib/python3.8/site-packages/gunicorn/app/wsgiapp.py", line 48, in load_wsgiapp
    return util.import_app(self.app_uri)
  File "/usr/local/lib/python3.8/site-packages/gunicorn/util.py", line 359, in import_app
    mod = importlib.import_module(module)
  File "/usr/local/lib/python3.8/importlib/__init__.py", line 127, in import_module
    return _bootstrap._gcd_import(name[level:], package, level)
  File "<frozen importlib._bootstrap>", line 1014, in _gcd_import
  File "<frozen importlib._bootstrap>", line 991, in _find_and_load
  File "<frozen importlib._bootstrap>", line 975, in _find_and_load_unlocked
  File "<frozen importlib._bootstrap>", line 671, in _load_unlocked
  File "<frozen importlib._bootstrap_external>", line 843, in exec_module
  File "<frozen importlib._bootstrap>", line 219, in _call_with_frames_removed
  File "/app/app/__init__.py", line 19, in <module>
    from app import routes
  File "/app/app/routes.py", line 9, in <module>
    from flask_jwt_extended import (
ImportError: cannot import name 'jwt_refresh_token_required' from 'flask_jwt_extended' (/usr/local/lib/python3.8/site-packages/flask_jwt_extended/__init__.py)
[2021-08-01 07:36:05 +0000] [10] [INFO] Worker exiting (pid: 10)
[2021-08-01 07:36:05 +0000] [9] [ERROR] Exception in worker process
Traceback (most recent call last):
  File "/usr/local/lib/python3.8/site-packages/gunicorn/arbiter.py", line 589, in spawn_worker
    worker.init_process()
  File "/usr/local/lib/python3.8/site-packages/gunicorn/workers/gthread.py", line 92, in init_process
    super().init_process()
  File "/usr/local/lib/python3.8/site-packages/gunicorn/workers/base.py", line 134, in init_process
    self.load_wsgi()
  File "/usr/local/lib/python3.8/site-packages/gunicorn/workers/base.py", line 146, in load_wsgi
    self.wsgi = self.app.wsgi()
  File "/usr/local/lib/python3.8/site-packages/gunicorn/app/base.py", line 67, in wsgi
    self.callable = self.load()
  File "/usr/local/lib/python3.8/site-packages/gunicorn/app/wsgiapp.py", line 58, in load
    return self.load_wsgiapp()
  File "/usr/local/lib/python3.8/site-packages/gunicorn/app/wsgiapp.py", line 48, in load_wsgiapp
    return util.import_app(self.app_uri)
  File "/usr/local/lib/python3.8/site-packages/gunicorn/util.py", line 359, in import_app
    mod = importlib.import_module(module)
  File "/usr/local/lib/python3.8/importlib/__init__.py", line 127, in import_module
    return _bootstrap._gcd_import(name[level:], package, level)
  File "<frozen importlib._bootstrap>", line 1014, in _gcd_import
  File "<frozen importlib._bootstrap>", line 991, in _find_and_load
  File "<frozen importlib._bootstrap>", line 975, in _find_and_load_unlocked
  File "<frozen importlib._bootstrap>", line 671, in _load_unlocked
  File "<frozen importlib._bootstrap_external>", line 843, in exec_module
  File "<frozen importlib._bootstrap>", line 219, in _call_with_frames_removed
  File "/app/app/__init__.py", line 19, in <module>
    from app import routes
  File "/app/app/routes.py", line 9, in <module>
    from flask_jwt_extended import (
ImportError: cannot import name 'jwt_refresh_token_required' from 'flask_jwt_extended' (/usr/local/lib/python3.8/site-packages/flask_jwt_extended/__init__.py)
[2021-08-01 07:36:05 +0000] [9] [INFO] Worker exiting (pid: 9)
[2021-08-01 07:36:08 +0000] [7] [INFO] Starting gunicorn 20.1.0
[2021-08-01 07:36:08 +0000] [7] [INFO] Listening at: http://0.0.0.0:5000 (7)
[2021-08-01 07:36:08 +0000] [7] [INFO] Using worker: gthread
[2021-08-01 07:36:08 +0000] [9] [INFO] Booting worker with pid: 9
[2021-08-01 07:36:08 +0000] [10] [INFO] Booting worker with pid: 10
[2021-08-01 07:36:08 +0000] [9] [ERROR] Exception in worker process
Traceback (most recent call last):
  File "/usr/local/lib/python3.8/site-packages/gunicorn/arbiter.py", line 589, in spawn_worker
    worker.init_process()
  File "/usr/local/lib/python3.8/site-packages/gunicorn/workers/gthread.py", line 92, in init_process
    super().init_process()
  File "/usr/local/lib/python3.8/site-packages/gunicorn/workers/base.py", line 134, in init_process
    self.load_wsgi()
  File "/usr/local/lib/python3.8/site-packages/gunicorn/workers/base.py", line 146, in load_wsgi
    self.wsgi = self.app.wsgi()
  File "/usr/local/lib/python3.8/site-packages/gunicorn/app/base.py", line 67, in wsgi
    self.callable = self.load()
  File "/usr/local/lib/python3.8/site-packages/gunicorn/app/wsgiapp.py", line 58, in load
    return self.load_wsgiapp()
  File "/usr/local/lib/python3.8/site-packages/gunicorn/app/wsgiapp.py", line 48, in load_wsgiapp
    return util.import_app(self.app_uri)
  File "/usr/local/lib/python3.8/site-packages/gunicorn/util.py", line 359, in import_app
    mod = importlib.import_module(module)
  File "/usr/local/lib/python3.8/importlib/__init__.py", line 127, in import_module
    return _bootstrap._gcd_import(name[level:], package, level)
  File "<frozen importlib._bootstrap>", line 1014, in _gcd_import
  File "<frozen importlib._bootstrap>", line 991, in _find_and_load
  File "<frozen importlib._bootstrap>", line 975, in _find_and_load_unlocked
  File "<frozen importlib._bootstrap>", line 671, in _load_unlocked
  File "<frozen importlib._bootstrap_external>", line 843, in exec_module
  File "<frozen importlib._bootstrap>", line 219, in _call_with_frames_removed
  File "/app/app/__init__.py", line 19, in <module>
    from app import routes
  File "/app/app/routes.py", line 9, in <module>
    from flask_jwt_extended import (
ImportError: cannot import name 'jwt_refresh_token_required' from 'flask_jwt_extended' (/usr/local/lib/python3.8/site-packages/flask_jwt_extended/__init__.py)
[2021-08-01 07:36:08 +0000] [9] [INFO] Worker exiting (pid: 9)
[2021-08-01 07:36:08 +0000] [10] [ERROR] Exception in worker process
Traceback (most recent call last):
  File "/usr/local/lib/python3.8/site-packages/gunicorn/arbiter.py", line 589, in spawn_worker
    worker.init_process()
  File "/usr/local/lib/python3.8/site-packages/gunicorn/workers/gthread.py", line 92, in init_process
    super().init_process()
  File "/usr/local/lib/python3.8/site-packages/gunicorn/workers/base.py", line 134, in init_process
    self.load_wsgi()
  File "/usr/local/lib/python3.8/site-packages/gunicorn/workers/base.py", line 146, in load_wsgi
    self.wsgi = self.app.wsgi()
  File "/usr/local/lib/python3.8/site-packages/gunicorn/app/base.py", line 67, in wsgi
    self.callable = self.load()
  File "/usr/local/lib/python3.8/site-packages/gunicorn/app/wsgiapp.py", line 58, in load
    return self.load_wsgiapp()
  File "/usr/local/lib/python3.8/site-packages/gunicorn/app/wsgiapp.py", line 48, in load_wsgiapp
    return util.import_app(self.app_uri)
  File "/usr/local/lib/python3.8/site-packages/gunicorn/util.py", line 359, in import_app
    mod = importlib.import_module(module)
  File "/usr/local/lib/python3.8/importlib/__init__.py", line 127, in import_module
    return _bootstrap._gcd_import(name[level:], package, level)
  File "<frozen importlib._bootstrap>", line 1014, in _gcd_import
  File "<frozen importlib._bootstrap>", line 991, in _find_and_load
  File "<frozen importlib._bootstrap>", line 975, in _find_and_load_unlocked
  File "<frozen importlib._bootstrap>", line 671, in _load_unlocked
  File "<frozen importlib._bootstrap_external>", line 843, in exec_module
  File "<frozen importlib._bootstrap>", line 219, in _call_with_frames_removed
  File "/app/app/__init__.py", line 19, in <module>
    from app import routes
  File "/app/app/routes.py", line 9, in <module>
    from flask_jwt_extended import (
ImportError: cannot import name 'jwt_refresh_token_required' from 'flask_jwt_extended' (/usr/local/lib/python3.8/site-packages/flask_jwt_extended/__init__.py)
[2021-08-01 07:36:08 +0000] [10] [INFO] Worker exiting (pid: 10)
[2021-08-01 07:36:11 +0000] [7] [INFO] Starting gunicorn 20.1.0
[2021-08-01 07:36:11 +0000] [7] [INFO] Listening at: http://0.0.0.0:5000 (7)
[2021-08-01 07:36:11 +0000] [7] [INFO] Using worker: gthread
[2021-08-01 07:36:11 +0000] [9] [INFO] Booting worker with pid: 9
[2021-08-01 07:36:11 +0000] [10] [INFO] Booting worker with pid: 10
[2021-08-01 07:36:12 +0000] [9] [ERROR] Exception in worker process
Traceback (most recent call last):
  File "/usr/local/lib/python3.8/site-packages/gunicorn/arbiter.py", line 589, in spawn_worker
    worker.init_process()
  File "/usr/local/lib/python3.8/site-packages/gunicorn/workers/gthread.py", line 92, in init_process
    super().init_process()
  File "/usr/local/lib/python3.8/site-packages/gunicorn/workers/base.py", line 134, in init_process
    self.load_wsgi()
  File "/usr/local/lib/python3.8/site-packages/gunicorn/workers/base.py", line 146, in load_wsgi
    self.wsgi = self.app.wsgi()
  File "/usr/local/lib/python3.8/site-packages/gunicorn/app/base.py", line 67, in wsgi
    self.callable = self.load()
  File "/usr/local/lib/python3.8/site-packages/gunicorn/app/wsgiapp.py", line 58, in load
    return self.load_wsgiapp()
  File "/usr/local/lib/python3.8/site-packages/gunicorn/app/wsgiapp.py", line 48, in load_wsgiapp
    return util.import_app(self.app_uri)
  File "/usr/local/lib/python3.8/site-packages/gunicorn/util.py", line 359, in import_app
    mod = importlib.import_module(module)
  File "/usr/local/lib/python3.8/importlib/__init__.py", line 127, in import_module
    return _bootstrap._gcd_import(name[level:], package, level)
  File "<frozen importlib._bootstrap>", line 1014, in _gcd_import
  File "<frozen importlib._bootstrap>", line 991, in _find_and_load
  File "<frozen importlib._bootstrap>", line 975, in _find_and_load_unlocked
  File "<frozen importlib._bootstrap>", line 671, in _load_unlocked
  File "<frozen importlib._bootstrap_external>", line 843, in exec_module
  File "<frozen importlib._bootstrap>", line 219, in _call_with_frames_removed
  File "/app/app/__init__.py", line 19, in <module>
    from app import routes
  File "/app/app/routes.py", line 9, in <module>
    from flask_jwt_extended import (
ImportError: cannot import name 'jwt_refresh_token_required' from 'flask_jwt_extended' (/usr/local/lib/python3.8/site-packages/flask_jwt_extended/__init__.py)
[2021-08-01 07:36:12 +0000] [9] [INFO] Worker exiting (pid: 9)
[2021-08-01 07:36:12 +0000] [10] [ERROR] Exception in worker process
Traceback (most recent call last):
  File "/usr/local/lib/python3.8/site-packages/gunicorn/arbiter.py", line 589, in spawn_worker
    worker.init_process()
  File "/usr/local/lib/python3.8/site-packages/gunicorn/workers/gthread.py", line 92, in init_process
    super().init_process()
  File "/usr/local/lib/python3.8/site-packages/gunicorn/workers/base.py", line 134, in init_process
    self.load_wsgi()
  File "/usr/local/lib/python3.8/site-packages/gunicorn/workers/base.py", line 146, in load_wsgi
    self.wsgi = self.app.wsgi()
  File "/usr/local/lib/python3.8/site-packages/gunicorn/app/base.py", line 67, in wsgi
    self.callable = self.load()
  File "/usr/local/lib/python3.8/site-packages/gunicorn/app/wsgiapp.py", line 58, in load
    return self.load_wsgiapp()
  File "/usr/local/lib/python3.8/site-packages/gunicorn/app/wsgiapp.py", line 48, in load_wsgiapp
    return util.import_app(self.app_uri)
  File "/usr/local/lib/python3.8/site-packages/gunicorn/util.py", line 359, in import_app
    mod = importlib.import_module(module)
  File "/usr/local/lib/python3.8/importlib/__init__.py", line 127, in import_module
    return _bootstrap._gcd_import(name[level:], package, level)
  File "<frozen importlib._bootstrap>", line 1014, in _gcd_import
  File "<frozen importlib._bootstrap>", line 991, in _find_and_load
  File "<frozen importlib._bootstrap>", line 975, in _find_and_load_unlocked
  File "<frozen importlib._bootstrap>", line 671, in _load_unlocked
  File "<frozen importlib._bootstrap_external>", line 843, in exec_module
  File "<frozen importlib._bootstrap>", line 219, in _call_with_frames_removed
  File "/app/app/__init__.py", line 19, in <module>
    from app import routes
  File "/app/app/routes.py", line 9, in <module>
    from flask_jwt_extended import (
ImportError: cannot import name 'jwt_refresh_token_required' from 'flask_jwt_extended' (/usr/local/lib/python3.8/site-packages/flask_jwt_extended/__init__.py)
[2021-08-01 07:36:12 +0000] [10] [INFO] Worker exiting (pid: 10)
[2021-08-01 07:36:12 +0000] [7] [WARNING] Worker with pid 10 was terminated due to signal 15
[2021-08-01 07:36:12 +0000] [7] [INFO] Shutting down: Master
[2021-08-01 07:36:12 +0000] [7] [INFO] Reason: Worker failed to boot.
[2021-08-01 07:36:14 +0000] [9] [INFO] Starting gunicorn 20.1.0
[2021-08-01 07:36:14 +0000] [9] [INFO] Listening at: http://0.0.0.0:5000 (9)
[2021-08-01 07:36:14 +0000] [9] [INFO] Using worker: gthread
[2021-08-01 07:36:14 +0000] [11] [INFO] Booting worker with pid: 11
[2021-08-01 07:36:14 +0000] [12] [INFO] Booting worker with pid: 12
[2021-08-01 07:36:15 +0000] [11] [ERROR] Exception in worker process
Traceback (most recent call last):
  File "/usr/local/lib/python3.8/site-packages/gunicorn/arbiter.py", line 589, in spawn_worker
    worker.init_process()
  File "/usr/local/lib/python3.8/site-packages/gunicorn/workers/gthread.py", line 92, in init_process
    super().init_process()
  File "/usr/local/lib/python3.8/site-packages/gunicorn/workers/base.py", line 134, in init_process
    self.load_wsgi()
  File "/usr/local/lib/python3.8/site-packages/gunicorn/workers/base.py", line 146, in load_wsgi
    self.wsgi = self.app.wsgi()
  File "/usr/local/lib/python3.8/site-packages/gunicorn/app/base.py", line 67, in wsgi
    self.callable = self.load()
  File "/usr/local/lib/python3.8/site-packages/gunicorn/app/wsgiapp.py", line 58, in load
    return self.load_wsgiapp()
  File "/usr/local/lib/python3.8/site-packages/gunicorn/app/wsgiapp.py", line 48, in load_wsgiapp
    return util.import_app(self.app_uri)
  File "/usr/local/lib/python3.8/site-packages/gunicorn/util.py", line 359, in import_app
    mod = importlib.import_module(module)
  File "/usr/local/lib/python3.8/importlib/__init__.py", line 127, in import_module
    return _bootstrap._gcd_import(name[level:], package, level)
  File "<frozen importlib._bootstrap>", line 1014, in _gcd_import
  File "<frozen importlib._bootstrap>", line 991, in _find_and_load
  File "<frozen importlib._bootstrap>", line 975, in _find_and_load_unlocked
  File "<frozen importlib._bootstrap>", line 671, in _load_unlocked
  File "<frozen importlib._bootstrap_external>", line 843, in exec_module
  File "<frozen importlib._bootstrap>", line 219, in _call_with_frames_removed
  File "/app/app/__init__.py", line 19, in <module>
    from app import routes
  File "/app/app/routes.py", line 9, in <module>
    from flask_jwt_extended import (
ImportError: cannot import name 'jwt_refresh_token_required' from 'flask_jwt_extended' (/usr/local/lib/python3.8/site-packages/flask_jwt_extended/__init__.py)
[2021-08-01 07:36:15 +0000] [11] [INFO] Worker exiting (pid: 11)
[2021-08-01 07:36:15 +0000] [12] [ERROR] Exception in worker process
Traceback (most recent call last):
  File "/usr/local/lib/python3.8/site-packages/gunicorn/arbiter.py", line 589, in spawn_worker
    worker.init_process()
  File "/usr/local/lib/python3.8/site-packages/gunicorn/workers/gthread.py", line 92, in init_process
    super().init_process()
  File "/usr/local/lib/python3.8/site-packages/gunicorn/workers/base.py", line 134, in init_process
    self.load_wsgi()
  File "/usr/local/lib/python3.8/site-packages/gunicorn/workers/base.py", line 146, in load_wsgi
    self.wsgi = self.app.wsgi()
  File "/usr/local/lib/python3.8/site-packages/gunicorn/app/base.py", line 67, in wsgi
    self.callable = self.load()
  File "/usr/local/lib/python3.8/site-packages/gunicorn/app/wsgiapp.py", line 58, in load
    return self.load_wsgiapp()
  File "/usr/local/lib/python3.8/site-packages/gunicorn/app/wsgiapp.py", line 48, in load_wsgiapp
    return util.import_app(self.app_uri)
  File "/usr/local/lib/python3.8/site-packages/gunicorn/util.py", line 359, in import_app
    mod = importlib.import_module(module)
  File "/usr/local/lib/python3.8/importlib/__init__.py", line 127, in import_module
    return _bootstrap._gcd_import(name[level:], package, level)
  File "<frozen importlib._bootstrap>", line 1014, in _gcd_import
  File "<frozen importlib._bootstrap>", line 991, in _find_and_load
  File "<frozen importlib._bootstrap>", line 975, in _find_and_load_unlocked
  File "<frozen importlib._bootstrap>", line 671, in _load_unlocked
  File "<frozen importlib._bootstrap_external>", line 843, in exec_module
  File "<frozen importlib._bootstrap>", line 219, in _call_with_frames_removed
  File "/app/app/__init__.py", line 19, in <module>
    from app import routes
  File "/app/app/routes.py", line 9, in <module>
    from flask_jwt_extended import (
ImportError: cannot import name 'jwt_refresh_token_required' from 'flask_jwt_extended' (/usr/local/lib/python3.8/site-packages/flask_jwt_extended/__init__.py)
[2021-08-01 07:36:15 +0000] [12] [INFO] Worker exiting (pid: 12)
[2021-08-01 07:36:15 +0000] [9] [WARNING] Worker with pid 12 was terminated due to signal 15
[2021-08-01 07:36:15 +0000] [9] [INFO] Shutting down: Master
[2021-08-01 07:36:15 +0000] [9] [INFO] Reason: Worker failed to boot.
[2021-08-01 07:36:17 +0000] [7] [INFO] Starting gunicorn 20.1.0
[2021-08-01 07:36:17 +0000] [7] [INFO] Listening at: http://0.0.0.0:5000 (7)
[2021-08-01 07:36:17 +0000] [7] [INFO] Using worker: gthread
[2021-08-01 07:36:17 +0000] [9] [INFO] Booting worker with pid: 9
[2021-08-01 07:36:18 +0000] [10] [INFO] Booting worker with pid: 10
[2021-08-01 07:36:18 +0000] [9] [ERROR] Exception in worker process
Traceback (most recent call last):
  File "/usr/local/lib/python3.8/site-packages/gunicorn/arbiter.py", line 589, in spawn_worker
    worker.init_process()
  File "/usr/local/lib/python3.8/site-packages/gunicorn/workers/gthread.py", line 92, in init_process
    super().init_process()
  File "/usr/local/lib/python3.8/site-packages/gunicorn/workers/base.py", line 134, in init_process
    self.load_wsgi()
  File "/usr/local/lib/python3.8/site-packages/gunicorn/workers/base.py", line 146, in load_wsgi
    self.wsgi = self.app.wsgi()
  File "/usr/local/lib/python3.8/site-packages/gunicorn/app/base.py", line 67, in wsgi
    self.callable = self.load()
  File "/usr/local/lib/python3.8/site-packages/gunicorn/app/wsgiapp.py", line 58, in load
    return self.load_wsgiapp()
  File "/usr/local/lib/python3.8/site-packages/gunicorn/app/wsgiapp.py", line 48, in load_wsgiapp
    return util.import_app(self.app_uri)
  File "/usr/local/lib/python3.8/site-packages/gunicorn/util.py", line 359, in import_app
    mod = importlib.import_module(module)
  File "/usr/local/lib/python3.8/importlib/__init__.py", line 127, in import_module
    return _bootstrap._gcd_import(name[level:], package, level)
  File "<frozen importlib._bootstrap>", line 1014, in _gcd_import
  File "<frozen importlib._bootstrap>", line 991, in _find_and_load
  File "<frozen importlib._bootstrap>", line 975, in _find_and_load_unlocked
  File "<frozen importlib._bootstrap>", line 671, in _load_unlocked
  File "<frozen importlib._bootstrap_external>", line 843, in exec_module
  File "<frozen importlib._bootstrap>", line 219, in _call_with_frames_removed
  File "/app/app/__init__.py", line 19, in <module>
    from app import routes
  File "/app/app/routes.py", line 9, in <module>
    from flask_jwt_extended import (
ImportError: cannot import name 'jwt_refresh_token_required' from 'flask_jwt_extended' (/usr/local/lib/python3.8/site-packages/flask_jwt_extended/__init__.py)
[2021-08-01 07:36:18 +0000] [9] [INFO] Worker exiting (pid: 9)
[2021-08-01 07:36:18 +0000] [10] [ERROR] Exception in worker process
Traceback (most recent call last):
  File "/usr/local/lib/python3.8/site-packages/gunicorn/arbiter.py", line 589, in spawn_worker
    worker.init_process()
  File "/usr/local/lib/python3.8/site-packages/gunicorn/workers/gthread.py", line 92, in init_process
    super().init_process()
  File "/usr/local/lib/python3.8/site-packages/gunicorn/workers/base.py", line 134, in init_process
    self.load_wsgi()
  File "/usr/local/lib/python3.8/site-packages/gunicorn/workers/base.py", line 146, in load_wsgi
    self.wsgi = self.app.wsgi()
  File "/usr/local/lib/python3.8/site-packages/gunicorn/app/base.py", line 67, in wsgi
    self.callable = self.load()
  File "/usr/local/lib/python3.8/site-packages/gunicorn/app/wsgiapp.py", line 58, in load
    return self.load_wsgiapp()
  File "/usr/local/lib/python3.8/site-packages/gunicorn/app/wsgiapp.py", line 48, in load_wsgiapp
    return util.import_app(self.app_uri)
  File "/usr/local/lib/python3.8/site-packages/gunicorn/util.py", line 359, in import_app
    mod = importlib.import_module(module)
  File "/usr/local/lib/python3.8/importlib/__init__.py", line 127, in import_module
    return _bootstrap._gcd_import(name[level:], package, level)
  File "<frozen importlib._bootstrap>", line 1014, in _gcd_import
  File "<frozen importlib._bootstrap>", line 991, in _find_and_load
  File "<frozen importlib._bootstrap>", line 975, in _find_and_load_unlocked
  File "<frozen importlib._bootstrap>", line 671, in _load_unlocked
  File "<frozen importlib._bootstrap_external>", line 843, in exec_module
  File "<frozen importlib._bootstrap>", line 219, in _call_with_frames_removed
  File "/app/app/__init__.py", line 19, in <module>
    from app import routes
  File "/app/app/routes.py", line 9, in <module>
    from flask_jwt_extended import (
ImportError: cannot import name 'jwt_refresh_token_required' from 'flask_jwt_extended' (/usr/local/lib/python3.8/site-packages/flask_jwt_extended/__init__.py)
[2021-08-01 07:36:18 +0000] [10] [INFO] Worker exiting (pid: 10)
[2021-08-01 07:36:21 +0000] [7] [INFO] Starting gunicorn 20.1.0
[2021-08-01 07:36:21 +0000] [7] [INFO] Listening at: http://0.0.0.0:5000 (7)
[2021-08-01 07:36:21 +0000] [7] [INFO] Using worker: gthread
[2021-08-01 07:36:21 +0000] [9] [INFO] Booting worker with pid: 9
[2021-08-01 07:36:21 +0000] [10] [INFO] Booting worker with pid: 10
[2021-08-01 07:36:22 +0000] [9] [ERROR] Exception in worker process
Traceback (most recent call last):
  File "/usr/local/lib/python3.8/site-packages/gunicorn/arbiter.py", line 589, in spawn_worker
    worker.init_process()
  File "/usr/local/lib/python3.8/site-packages/gunicorn/workers/gthread.py", line 92, in init_process
    super().init_process()
  File "/usr/local/lib/python3.8/site-packages/gunicorn/workers/base.py", line 134, in init_process
    self.load_wsgi()
  File "/usr/local/lib/python3.8/site-packages/gunicorn/workers/base.py", line 146, in load_wsgi
    self.wsgi = self.app.wsgi()
  File "/usr/local/lib/python3.8/site-packages/gunicorn/app/base.py", line 67, in wsgi
    self.callable = self.load()
  File "/usr/local/lib/python3.8/site-packages/gunicorn/app/wsgiapp.py", line 58, in load
    return self.load_wsgiapp()
  File "/usr/local/lib/python3.8/site-packages/gunicorn/app/wsgiapp.py", line 48, in load_wsgiapp
    return util.import_app(self.app_uri)
  File "/usr/local/lib/python3.8/site-packages/gunicorn/util.py", line 359, in import_app
    mod = importlib.import_module(module)
  File "/usr/local/lib/python3.8/importlib/__init__.py", line 127, in import_module
    return _bootstrap._gcd_import(name[level:], package, level)
  File "<frozen importlib._bootstrap>", line 1014, in _gcd_import
  File "<frozen importlib._bootstrap>", line 991, in _find_and_load
  File "<frozen importlib._bootstrap>", line 975, in _find_and_load_unlocked
  File "<frozen importlib._bootstrap>", line 671, in _load_unlocked
  File "<frozen importlib._bootstrap_external>", line 843, in exec_module
  File "<frozen importlib._bootstrap>", line 219, in _call_with_frames_removed
  File "/app/app/__init__.py", line 19, in <module>
    from app import routes
  File "/app/app/routes.py", line 9, in <module>
    from flask_jwt_extended import (
ImportError: cannot import name 'jwt_refresh_token_required' from 'flask_jwt_extended' (/usr/local/lib/python3.8/site-packages/flask_jwt_extended/__init__.py)
[2021-08-01 07:36:22 +0000] [9] [INFO] Worker exiting (pid: 9)
[2021-08-01 07:36:22 +0000] [10] [ERROR] Exception in worker process
Traceback (most recent call last):
  File "/usr/local/lib/python3.8/site-packages/gunicorn/arbiter.py", line 589, in spawn_worker
    worker.init_process()
  File "/usr/local/lib/python3.8/site-packages/gunicorn/workers/gthread.py", line 92, in init_process
    super().init_process()
  File "/usr/local/lib/python3.8/site-packages/gunicorn/workers/base.py", line 134, in init_process
    self.load_wsgi()
  File "/usr/local/lib/python3.8/site-packages/gunicorn/workers/base.py", line 146, in load_wsgi
    self.wsgi = self.app.wsgi()
  File "/usr/local/lib/python3.8/site-packages/gunicorn/app/base.py", line 67, in wsgi
    self.callable = self.load()
  File "/usr/local/lib/python3.8/site-packages/gunicorn/app/wsgiapp.py", line 58, in load
    return self.load_wsgiapp()
  File "/usr/local/lib/python3.8/site-packages/gunicorn/app/wsgiapp.py", line 48, in load_wsgiapp
    return util.import_app(self.app_uri)
  File "/usr/local/lib/python3.8/site-packages/gunicorn/util.py", line 359, in import_app
    mod = importlib.import_module(module)
  File "/usr/local/lib/python3.8/importlib/__init__.py", line 127, in import_module
    return _bootstrap._gcd_import(name[level:], package, level)
  File "<frozen importlib._bootstrap>", line 1014, in _gcd_import
  File "<frozen importlib._bootstrap>", line 991, in _find_and_load
  File "<frozen importlib._bootstrap>", line 975, in _find_and_load_unlocked
  File "<frozen importlib._bootstrap>", line 671, in _load_unlocked
  File "<frozen importlib._bootstrap_external>", line 843, in exec_module
  File "<frozen importlib._bootstrap>", line 219, in _call_with_frames_removed
  File "/app/app/__init__.py", line 19, in <module>
    from app import routes
  File "/app/app/routes.py", line 9, in <module>
    from flask_jwt_extended import (
ImportError: cannot import name 'jwt_refresh_token_required' from 'flask_jwt_extended' (/usr/local/lib/python3.8/site-packages/flask_jwt_extended/__init__.py)
[2021-08-01 07:36:22 +0000] [10] [INFO] Worker exiting (pid: 10)
[2021-08-01 07:36:27 +0000] [9] [INFO] Starting gunicorn 20.1.0
[2021-08-01 07:36:27 +0000] [9] [INFO] Listening at: http://0.0.0.0:5000 (9)
[2021-08-01 07:36:27 +0000] [9] [INFO] Using worker: gthread
[2021-08-01 07:36:27 +0000] [11] [INFO] Booting worker with pid: 11
[2021-08-01 07:36:27 +0000] [12] [INFO] Booting worker with pid: 12
[2021-08-01 07:36:27 +0000] [11] [ERROR] Exception in worker process
Traceback (most recent call last):
  File "/usr/local/lib/python3.8/site-packages/gunicorn/arbiter.py", line 589, in spawn_worker
    worker.init_process()
  File "/usr/local/lib/python3.8/site-packages/gunicorn/workers/gthread.py", line 92, in init_process
    super().init_process()
  File "/usr/local/lib/python3.8/site-packages/gunicorn/workers/base.py", line 134, in init_process
    self.load_wsgi()
  File "/usr/local/lib/python3.8/site-packages/gunicorn/workers/base.py", line 146, in load_wsgi
    self.wsgi = self.app.wsgi()
  File "/usr/local/lib/python3.8/site-packages/gunicorn/app/base.py", line 67, in wsgi
    self.callable = self.load()
  File "/usr/local/lib/python3.8/site-packages/gunicorn/app/wsgiapp.py", line 58, in load
    return self.load_wsgiapp()
  File "/usr/local/lib/python3.8/site-packages/gunicorn/app/wsgiapp.py", line 48, in load_wsgiapp
    return util.import_app(self.app_uri)
  File "/usr/local/lib/python3.8/site-packages/gunicorn/util.py", line 359, in import_app
    mod = importlib.import_module(module)
  File "/usr/local/lib/python3.8/importlib/__init__.py", line 127, in import_module
    return _bootstrap._gcd_import(name[level:], package, level)
  File "<frozen importlib._bootstrap>", line 1014, in _gcd_import
  File "<frozen importlib._bootstrap>", line 991, in _find_and_load
  File "<frozen importlib._bootstrap>", line 975, in _find_and_load_unlocked
  File "<frozen importlib._bootstrap>", line 671, in _load_unlocked
  File "<frozen importlib._bootstrap_external>", line 843, in exec_module
  File "<frozen importlib._bootstrap>", line 219, in _call_with_frames_removed
  File "/app/app/__init__.py", line 19, in <module>
    from app import routes
  File "/app/app/routes.py", line 9, in <module>
    from flask_jwt_extended import (
ImportError: cannot import name 'jwt_refresh_token_required' from 'flask_jwt_extended' (/usr/local/lib/python3.8/site-packages/flask_jwt_extended/__init__.py)
[2021-08-01 07:36:27 +0000] [11] [INFO] Worker exiting (pid: 11)
[2021-08-01 07:36:27 +0000] [12] [ERROR] Exception in worker process
Traceback (most recent call last):
  File "/usr/local/lib/python3.8/site-packages/gunicorn/arbiter.py", line 589, in spawn_worker
    worker.init_process()
  File "/usr/local/lib/python3.8/site-packages/gunicorn/workers/gthread.py", line 92, in init_process
    super().init_process()
  File "/usr/local/lib/python3.8/site-packages/gunicorn/workers/base.py", line 134, in init_process
    self.load_wsgi()
  File "/usr/local/lib/python3.8/site-packages/gunicorn/workers/base.py", line 146, in load_wsgi
    self.wsgi = self.app.wsgi()
  File "/usr/local/lib/python3.8/site-packages/gunicorn/app/base.py", line 67, in wsgi
    self.callable = self.load()
  File "/usr/local/lib/python3.8/site-packages/gunicorn/app/wsgiapp.py", line 58, in load
    return self.load_wsgiapp()
  File "/usr/local/lib/python3.8/site-packages/gunicorn/app/wsgiapp.py", line 48, in load_wsgiapp
    return util.import_app(self.app_uri)
  File "/usr/local/lib/python3.8/site-packages/gunicorn/util.py", line 359, in import_app
    mod = importlib.import_module(module)
  File "/usr/local/lib/python3.8/importlib/__init__.py", line 127, in import_module
    return _bootstrap._gcd_import(name[level:], package, level)
  File "<frozen importlib._bootstrap>", line 1014, in _gcd_import
  File "<frozen importlib._bootstrap>", line 991, in _find_and_load
  File "<frozen importlib._bootstrap>", line 975, in _find_and_load_unlocked
  File "<frozen importlib._bootstrap>", line 671, in _load_unlocked
  File "<frozen importlib._bootstrap_external>", line 843, in exec_module
  File "<frozen importlib._bootstrap>", line 219, in _call_with_frames_removed
  File "/app/app/__init__.py", line 19, in <module>
    from app import routes
  File "/app/app/routes.py", line 9, in <module>
    from flask_jwt_extended import (
ImportError: cannot import name 'jwt_refresh_token_required' from 'flask_jwt_extended' (/usr/local/lib/python3.8/site-packages/flask_jwt_extended/__init__.py)
[2021-08-01 07:36:27 +0000] [12] [INFO] Worker exiting (pid: 12)
[2021-08-01 07:36:27 +0000] [9] [WARNING] Worker with pid 12 was terminated due to signal 15
[2021-08-01 07:36:27 +0000] [9] [INFO] Shutting down: Master
[2021-08-01 07:36:27 +0000] [9] [INFO] Reason: Worker failed to boot.
[2021-08-01 07:36:35 +0000] [10] [INFO] Starting gunicorn 20.1.0
[2021-08-01 07:36:35 +0000] [10] [INFO] Listening at: http://0.0.0.0:5000 (10)
[2021-08-01 07:36:35 +0000] [10] [INFO] Using worker: gthread
[2021-08-01 07:36:35 +0000] [12] [INFO] Booting worker with pid: 12
[2021-08-01 07:36:35 +0000] [13] [INFO] Booting worker with pid: 13
[2021-08-01 07:36:36 +0000] [12] [ERROR] Exception in worker process
Traceback (most recent call last):
  File "/usr/local/lib/python3.8/site-packages/gunicorn/arbiter.py", line 589, in spawn_worker
    worker.init_process()
  File "/usr/local/lib/python3.8/site-packages/gunicorn/workers/gthread.py", line 92, in init_process
    super().init_process()
  File "/usr/local/lib/python3.8/site-packages/gunicorn/workers/base.py", line 134, in init_process
    self.load_wsgi()
  File "/usr/local/lib/python3.8/site-packages/gunicorn/workers/base.py", line 146, in load_wsgi
    self.wsgi = self.app.wsgi()
  File "/usr/local/lib/python3.8/site-packages/gunicorn/app/base.py", line 67, in wsgi
    self.callable = self.load()
  File "/usr/local/lib/python3.8/site-packages/gunicorn/app/wsgiapp.py", line 58, in load
    return self.load_wsgiapp()
  File "/usr/local/lib/python3.8/site-packages/gunicorn/app/wsgiapp.py", line 48, in load_wsgiapp
    return util.import_app(self.app_uri)
  File "/usr/local/lib/python3.8/site-packages/gunicorn/util.py", line 359, in import_app
    mod = importlib.import_module(module)
  File "/usr/local/lib/python3.8/importlib/__init__.py", line 127, in import_module
    return _bootstrap._gcd_import(name[level:], package, level)
  File "<frozen importlib._bootstrap>", line 1014, in _gcd_import
  File "<frozen importlib._bootstrap>", line 991, in _find_and_load
  File "<frozen importlib._bootstrap>", line 975, in _find_and_load_unlocked
  File "<frozen importlib._bootstrap>", line 671, in _load_unlocked
  File "<frozen importlib._bootstrap_external>", line 843, in exec_module
  File "<frozen importlib._bootstrap>", line 219, in _call_with_frames_removed
  File "/app/app/__init__.py", line 19, in <module>
    from app import routes
  File "/app/app/routes.py", line 9, in <module>
    from flask_jwt_extended import (
ImportError: cannot import name 'jwt_refresh_token_required' from 'flask_jwt_extended' (/usr/local/lib/python3.8/site-packages/flask_jwt_extended/__init__.py)
[2021-08-01 07:36:36 +0000] [12] [INFO] Worker exiting (pid: 12)
[2021-08-01 07:36:36 +0000] [13] [ERROR] Exception in worker process
Traceback (most recent call last):
  File "/usr/local/lib/python3.8/site-packages/gunicorn/arbiter.py", line 589, in spawn_worker
    worker.init_process()
  File "/usr/local/lib/python3.8/site-packages/gunicorn/workers/gthread.py", line 92, in init_process
    super().init_process()
  File "/usr/local/lib/python3.8/site-packages/gunicorn/workers/base.py", line 134, in init_process
    self.load_wsgi()
  File "/usr/local/lib/python3.8/site-packages/gunicorn/workers/base.py", line 146, in load_wsgi
    self.wsgi = self.app.wsgi()
  File "/usr/local/lib/python3.8/site-packages/gunicorn/app/base.py", line 67, in wsgi
    self.callable = self.load()
  File "/usr/local/lib/python3.8/site-packages/gunicorn/app/wsgiapp.py", line 58, in load
    return self.load_wsgiapp()
  File "/usr/local/lib/python3.8/site-packages/gunicorn/app/wsgiapp.py", line 48, in load_wsgiapp
    return util.import_app(self.app_uri)
  File "/usr/local/lib/python3.8/site-packages/gunicorn/util.py", line 359, in import_app
    mod = importlib.import_module(module)
  File "/usr/local/lib/python3.8/importlib/__init__.py", line 127, in import_module
    return _bootstrap._gcd_import(name[level:], package, level)
  File "<frozen importlib._bootstrap>", line 1014, in _gcd_import
  File "<frozen importlib._bootstrap>", line 991, in _find_and_load
  File "<frozen importlib._bootstrap>", line 975, in _find_and_load_unlocked
  File "<frozen importlib._bootstrap>", line 671, in _load_unlocked
  File "<frozen importlib._bootstrap_external>", line 843, in exec_module
  File "<frozen importlib._bootstrap>", line 219, in _call_with_frames_removed
  File "/app/app/__init__.py", line 19, in <module>
    from app import routes
  File "/app/app/routes.py", line 9, in <module>
    from flask_jwt_extended import (
ImportError: cannot import name 'jwt_refresh_token_required' from 'flask_jwt_extended' (/usr/local/lib/python3.8/site-packages/flask_jwt_extended/__init__.py)
[2021-08-01 07:36:36 +0000] [13] [INFO] Worker exiting (pid: 13)
[2021-08-01 07:36:50 +0000] [9] [INFO] Starting gunicorn 20.1.0
[2021-08-01 07:36:50 +0000] [9] [INFO] Listening at: http://0.0.0.0:5000 (9)
[2021-08-01 07:36:50 +0000] [9] [INFO] Using worker: gthread
[2021-08-01 07:36:50 +0000] [11] [INFO] Booting worker with pid: 11
[2021-08-01 07:36:50 +0000] [12] [INFO] Booting worker with pid: 12
[2021-08-01 07:36:51 +0000] [11] [ERROR] Exception in worker process
Traceback (most recent call last):
  File "/usr/local/lib/python3.8/site-packages/gunicorn/arbiter.py", line 589, in spawn_worker
    worker.init_process()
  File "/usr/local/lib/python3.8/site-packages/gunicorn/workers/gthread.py", line 92, in init_process
    super().init_process()
  File "/usr/local/lib/python3.8/site-packages/gunicorn/workers/base.py", line 134, in init_process
    self.load_wsgi()
  File "/usr/local/lib/python3.8/site-packages/gunicorn/workers/base.py", line 146, in load_wsgi
    self.wsgi = self.app.wsgi()
  File "/usr/local/lib/python3.8/site-packages/gunicorn/app/base.py", line 67, in wsgi
    self.callable = self.load()
  File "/usr/local/lib/python3.8/site-packages/gunicorn/app/wsgiapp.py", line 58, in load
    return self.load_wsgiapp()
  File "/usr/local/lib/python3.8/site-packages/gunicorn/app/wsgiapp.py", line 48, in load_wsgiapp
    return util.import_app(self.app_uri)
  File "/usr/local/lib/python3.8/site-packages/gunicorn/util.py", line 359, in import_app
    mod = importlib.import_module(module)
  File "/usr/local/lib/python3.8/importlib/__init__.py", line 127, in import_module
    return _bootstrap._gcd_import(name[level:], package, level)
  File "<frozen importlib._bootstrap>", line 1014, in _gcd_import
  File "<frozen importlib._bootstrap>", line 991, in _find_and_load
  File "<frozen importlib._bootstrap>", line 975, in _find_and_load_unlocked
  File "<frozen importlib._bootstrap>", line 671, in _load_unlocked
  File "<frozen importlib._bootstrap_external>", line 843, in exec_module
  File "<frozen importlib._bootstrap>", line 219, in _call_with_frames_removed
  File "/app/app/__init__.py", line 19, in <module>
    from app import routes
  File "/app/app/routes.py", line 9, in <module>
    from flask_jwt_extended import (
ImportError: cannot import name 'jwt_refresh_token_required' from 'flask_jwt_extended' (/usr/local/lib/python3.8/site-packages/flask_jwt_extended/__init__.py)
[2021-08-01 07:36:51 +0000] [11] [INFO] Worker exiting (pid: 11)
[2021-08-01 07:36:51 +0000] [12] [ERROR] Exception in worker process
Traceback (most recent call last):
  File "/usr/local/lib/python3.8/site-packages/gunicorn/arbiter.py", line 589, in spawn_worker
    worker.init_process()
  File "/usr/local/lib/python3.8/site-packages/gunicorn/workers/gthread.py", line 92, in init_process
    super().init_process()
  File "/usr/local/lib/python3.8/site-packages/gunicorn/workers/base.py", line 134, in init_process
    self.load_wsgi()
  File "/usr/local/lib/python3.8/site-packages/gunicorn/workers/base.py", line 146, in load_wsgi
    self.wsgi = self.app.wsgi()
  File "/usr/local/lib/python3.8/site-packages/gunicorn/app/base.py", line 67, in wsgi
    self.callable = self.load()
  File "/usr/local/lib/python3.8/site-packages/gunicorn/app/wsgiapp.py", line 58, in load
    return self.load_wsgiapp()
  File "/usr/local/lib/python3.8/site-packages/gunicorn/app/wsgiapp.py", line 48, in load_wsgiapp
    return util.import_app(self.app_uri)
  File "/usr/local/lib/python3.8/site-packages/gunicorn/util.py", line 359, in import_app
    mod = importlib.import_module(module)
  File "/usr/local/lib/python3.8/importlib/__init__.py", line 127, in import_module
    return _bootstrap._gcd_import(name[level:], package, level)
  File "<frozen importlib._bootstrap>", line 1014, in _gcd_import
  File "<frozen importlib._bootstrap>", line 991, in _find_and_load
  File "<frozen importlib._bootstrap>", line 975, in _find_and_load_unlocked
  File "<frozen importlib._bootstrap>", line 671, in _load_unlocked
  File "<frozen importlib._bootstrap_external>", line 843, in exec_module
  File "<frozen importlib._bootstrap>", line 219, in _call_with_frames_removed
  File "/app/app/__init__.py", line 19, in <module>
    from app import routes
  File "/app/app/routes.py", line 9, in <module>
    from flask_jwt_extended import (
ImportError: cannot import name 'jwt_refresh_token_required' from 'flask_jwt_extended' (/usr/local/lib/python3.8/site-packages/flask_jwt_extended/__init__.py)
[2021-08-01 07:36:51 +0000] [12] [INFO] Worker exiting (pid: 12)
[2021-08-01 07:36:51 +0000] [9] [WARNING] Worker with pid 12 was terminated due to signal 15
[2021-08-01 07:36:51 +0000] [9] [INFO] Shutting down: Master
[2021-08-01 07:36:51 +0000] [9] [INFO] Reason: Worker failed to boot.
[2021-08-01 07:37:18 +0000] [7] [INFO] Starting gunicorn 20.1.0
[2021-08-01 07:37:18 +0000] [7] [INFO] Listening at: http://0.0.0.0:5000 (7)
[2021-08-01 07:37:18 +0000] [7] [INFO] Using worker: gthread
[2021-08-01 07:37:18 +0000] [9] [INFO] Booting worker with pid: 9
[2021-08-01 07:37:18 +0000] [10] [INFO] Booting worker with pid: 10
[2021-08-01 07:37:18 +0000] [9] [ERROR] Exception in worker process
Traceback (most recent call last):
  File "/usr/local/lib/python3.8/site-packages/gunicorn/arbiter.py", line 589, in spawn_worker
    worker.init_process()
  File "/usr/local/lib/python3.8/site-packages/gunicorn/workers/gthread.py", line 92, in init_process
    super().init_process()
  File "/usr/local/lib/python3.8/site-packages/gunicorn/workers/base.py", line 134, in init_process
    self.load_wsgi()
  File "/usr/local/lib/python3.8/site-packages/gunicorn/workers/base.py", line 146, in load_wsgi
    self.wsgi = self.app.wsgi()
  File "/usr/local/lib/python3.8/site-packages/gunicorn/app/base.py", line 67, in wsgi
    self.callable = self.load()
  File "/usr/local/lib/python3.8/site-packages/gunicorn/app/wsgiapp.py", line 58, in load
    return self.load_wsgiapp()
  File "/usr/local/lib/python3.8/site-packages/gunicorn/app/wsgiapp.py", line 48, in load_wsgiapp
    return util.import_app(self.app_uri)
  File "/usr/local/lib/python3.8/site-packages/gunicorn/util.py", line 359, in import_app
    mod = importlib.import_module(module)
  File "/usr/local/lib/python3.8/importlib/__init__.py", line 127, in import_module
    return _bootstrap._gcd_import(name[level:], package, level)
  File "<frozen importlib._bootstrap>", line 1014, in _gcd_import
  File "<frozen importlib._bootstrap>", line 991, in _find_and_load
  File "<frozen importlib._bootstrap>", line 975, in _find_and_load_unlocked
  File "<frozen importlib._bootstrap>", line 671, in _load_unlocked
  File "<frozen importlib._bootstrap_external>", line 843, in exec_module
  File "<frozen importlib._bootstrap>", line 219, in _call_with_frames_removed
  File "/app/app/__init__.py", line 19, in <module>
    from app import routes
  File "/app/app/routes.py", line 9, in <module>
    from flask_jwt_extended import (
ImportError: cannot import name 'jwt_refresh_token_required' from 'flask_jwt_extended' (/usr/local/lib/python3.8/site-packages/flask_jwt_extended/__init__.py)
[2021-08-01 07:37:18 +0000] [9] [INFO] Worker exiting (pid: 9)
[2021-08-01 07:37:18 +0000] [10] [ERROR] Exception in worker process
Traceback (most recent call last):
  File "/usr/local/lib/python3.8/site-packages/gunicorn/arbiter.py", line 589, in spawn_worker
    worker.init_process()
  File "/usr/local/lib/python3.8/site-packages/gunicorn/workers/gthread.py", line 92, in init_process
    super().init_process()
  File "/usr/local/lib/python3.8/site-packages/gunicorn/workers/base.py", line 134, in init_process
    self.load_wsgi()
  File "/usr/local/lib/python3.8/site-packages/gunicorn/workers/base.py", line 146, in load_wsgi
    self.wsgi = self.app.wsgi()
  File "/usr/local/lib/python3.8/site-packages/gunicorn/app/base.py", line 67, in wsgi
    self.callable = self.load()
  File "/usr/local/lib/python3.8/site-packages/gunicorn/app/wsgiapp.py", line 58, in load
    return self.load_wsgiapp()
  File "/usr/local/lib/python3.8/site-packages/gunicorn/app/wsgiapp.py", line 48, in load_wsgiapp
    return util.import_app(self.app_uri)
  File "/usr/local/lib/python3.8/site-packages/gunicorn/util.py", line 359, in import_app
    mod = importlib.import_module(module)
  File "/usr/local/lib/python3.8/importlib/__init__.py", line 127, in import_module
    return _bootstrap._gcd_import(name[level:], package, level)
  File "<frozen importlib._bootstrap>", line 1014, in _gcd_import
  File "<frozen importlib._bootstrap>", line 991, in _find_and_load
  File "<frozen importlib._bootstrap>", line 975, in _find_and_load_unlocked
  File "<frozen importlib._bootstrap>", line 671, in _load_unlocked
  File "<frozen importlib._bootstrap_external>", line 843, in exec_module
  File "<frozen importlib._bootstrap>", line 219, in _call_with_frames_removed
  File "/app/app/__init__.py", line 19, in <module>
    from app import routes
  File "/app/app/routes.py", line 9, in <module>
    from flask_jwt_extended import (
ImportError: cannot import name 'jwt_refresh_token_required' from 'flask_jwt_extended' (/usr/local/lib/python3.8/site-packages/flask_jwt_extended/__init__.py)
[2021-08-01 07:37:18 +0000] [10] [INFO] Worker exiting (pid: 10)
[2021-08-01 07:38:11 +0000] [8] [INFO] Starting gunicorn 20.1.0
[2021-08-01 07:38:11 +0000] [8] [INFO] Listening at: http://0.0.0.0:5000 (8)
[2021-08-01 07:38:11 +0000] [8] [INFO] Using worker: gthread
[2021-08-01 07:38:11 +0000] [10] [INFO] Booting worker with pid: 10
[2021-08-01 07:38:11 +0000] [11] [INFO] Booting worker with pid: 11
[2021-08-01 07:38:12 +0000] [11] [ERROR] Exception in worker process
Traceback (most recent call last):
  File "/usr/local/lib/python3.8/site-packages/gunicorn/arbiter.py", line 589, in spawn_worker
    worker.init_process()
  File "/usr/local/lib/python3.8/site-packages/gunicorn/workers/gthread.py", line 92, in init_process
    super().init_process()
  File "/usr/local/lib/python3.8/site-packages/gunicorn/workers/base.py", line 134, in init_process
    self.load_wsgi()
  File "/usr/local/lib/python3.8/site-packages/gunicorn/workers/base.py", line 146, in load_wsgi
    self.wsgi = self.app.wsgi()
  File "/usr/local/lib/python3.8/site-packages/gunicorn/app/base.py", line 67, in wsgi
    self.callable = self.load()
  File "/usr/local/lib/python3.8/site-packages/gunicorn/app/wsgiapp.py", line 58, in load
    return self.load_wsgiapp()
  File "/usr/local/lib/python3.8/site-packages/gunicorn/app/wsgiapp.py", line 48, in load_wsgiapp
    return util.import_app(self.app_uri)
  File "/usr/local/lib/python3.8/site-packages/gunicorn/util.py", line 359, in import_app
    mod = importlib.import_module(module)
  File "/usr/local/lib/python3.8/importlib/__init__.py", line 127, in import_module
    return _bootstrap._gcd_import(name[level:], package, level)
  File "<frozen importlib._bootstrap>", line 1014, in _gcd_import
  File "<frozen importlib._bootstrap>", line 991, in _find_and_load
  File "<frozen importlib._bootstrap>", line 975, in _find_and_load_unlocked
  File "<frozen importlib._bootstrap>", line 671, in _load_unlocked
  File "<frozen importlib._bootstrap_external>", line 843, in exec_module
  File "<frozen importlib._bootstrap>", line 219, in _call_with_frames_removed
  File "/app/app/__init__.py", line 19, in <module>
    from app import routes
  File "/app/app/routes.py", line 9, in <module>
    from flask_jwt_extended import (
ImportError: cannot import name 'jwt_refresh_token_required' from 'flask_jwt_extended' (/usr/local/lib/python3.8/site-packages/flask_jwt_extended/__init__.py)
[2021-08-01 07:38:12 +0000] [11] [INFO] Worker exiting (pid: 11)
[2021-08-01 07:38:12 +0000] [10] [ERROR] Exception in worker process
Traceback (most recent call last):
  File "/usr/local/lib/python3.8/site-packages/gunicorn/arbiter.py", line 589, in spawn_worker
    worker.init_process()
  File "/usr/local/lib/python3.8/site-packages/gunicorn/workers/gthread.py", line 92, in init_process
    super().init_process()
  File "/usr/local/lib/python3.8/site-packages/gunicorn/workers/base.py", line 134, in init_process
    self.load_wsgi()
  File "/usr/local/lib/python3.8/site-packages/gunicorn/workers/base.py", line 146, in load_wsgi
    self.wsgi = self.app.wsgi()
  File "/usr/local/lib/python3.8/site-packages/gunicorn/app/base.py", line 67, in wsgi
    self.callable = self.load()
  File "/usr/local/lib/python3.8/site-packages/gunicorn/app/wsgiapp.py", line 58, in load
    return self.load_wsgiapp()
  File "/usr/local/lib/python3.8/site-packages/gunicorn/app/wsgiapp.py", line 48, in load_wsgiapp
    return util.import_app(self.app_uri)
  File "/usr/local/lib/python3.8/site-packages/gunicorn/util.py", line 359, in import_app
    mod = importlib.import_module(module)
  File "/usr/local/lib/python3.8/importlib/__init__.py", line 127, in import_module
    return _bootstrap._gcd_import(name[level:], package, level)
  File "<frozen importlib._bootstrap>", line 1014, in _gcd_import
  File "<frozen importlib._bootstrap>", line 991, in _find_and_load
  File "<frozen importlib._bootstrap>", line 975, in _find_and_load_unlocked
  File "<frozen importlib._bootstrap>", line 671, in _load_unlocked
  File "<frozen importlib._bootstrap_external>", line 843, in exec_module
  File "<frozen importlib._bootstrap>", line 219, in _call_with_frames_removed
  File "/app/app/__init__.py", line 19, in <module>
    from app import routes
  File "/app/app/routes.py", line 9, in <module>
    from flask_jwt_extended import (
ImportError: cannot import name 'jwt_refresh_token_required' from 'flask_jwt_extended' (/usr/local/lib/python3.8/site-packages/flask_jwt_extended/__init__.py)
[2021-08-01 07:38:12 +0000] [10] [INFO] Worker exiting (pid: 10)
[2021-08-01 07:39:13 +0000] [7] [INFO] Starting gunicorn 20.1.0
[2021-08-01 07:39:13 +0000] [7] [INFO] Listening at: http://0.0.0.0:5000 (7)
[2021-08-01 07:39:13 +0000] [7] [INFO] Using worker: gthread
[2021-08-01 07:39:13 +0000] [9] [INFO] Booting worker with pid: 9
[2021-08-01 07:39:13 +0000] [10] [INFO] Booting worker with pid: 10
[2021-08-01 07:40:35 +0000] [7] [INFO] Starting gunicorn 20.1.0
[2021-08-01 07:40:35 +0000] [7] [INFO] Listening at: http://0.0.0.0:5000 (7)
[2021-08-01 07:40:35 +0000] [7] [INFO] Using worker: gthread
[2021-08-01 07:40:35 +0000] [9] [INFO] Booting worker with pid: 9
[2021-08-01 07:40:35 +0000] [10] [INFO] Booting worker with pid: 10
[2021-08-01 07:50:03,364] ERROR in app: Exception on /refresh [POST]
Traceback (most recent call last):
  File "/usr/local/lib/python3.8/site-packages/flask/app.py", line 2070, in wsgi_app
    response = self.full_dispatch_request()
  File "/usr/local/lib/python3.8/site-packages/flask/app.py", line 1515, in full_dispatch_request
    rv = self.handle_user_exception(e)
  File "/usr/local/lib/python3.8/site-packages/flask_cors/extension.py", line 165, in wrapped_function
    return cors_after_request(app.make_response(f(*args, **kwargs)))
  File "/usr/local/lib/python3.8/site-packages/flask/app.py", line 1513, in full_dispatch_request
    rv = self.dispatch_request()
  File "/usr/local/lib/python3.8/site-packages/flask/app.py", line 1499, in dispatch_request
    return self.ensure_sync(self.view_functions[rule.endpoint])(**req.view_args)
  File "/usr/local/lib/python3.8/site-packages/flask_jwt_extended/view_decorators.py", line 125, in decorator
    return current_app.ensure_sync(fn)(*args, **kwargs)
  File "/app/app/routes.py", line 53, in refresh
    claims = get_jwt()
NameError: name 'get_jwt' is not defined
[2021-08-01 07:51:45 +0000] [7] [INFO] Starting gunicorn 20.1.0
[2021-08-01 07:51:45 +0000] [7] [INFO] Listening at: http://0.0.0.0:5000 (7)
[2021-08-01 07:51:45 +0000] [7] [INFO] Using worker: gthread
[2021-08-01 07:51:45 +0000] [9] [INFO] Booting worker with pid: 9
[2021-08-01 07:51:45 +0000] [10] [INFO] Booting worker with pid: 10
[2021-08-01 07:57:20 +0000] [7] [INFO] Starting gunicorn 20.1.0
[2021-08-01 07:57:20 +0000] [7] [INFO] Listening at: http://0.0.0.0:5000 (7)
[2021-08-01 07:57:20 +0000] [7] [INFO] Using worker: gthread
[2021-08-01 07:57:20 +0000] [9] [INFO] Booting worker with pid: 9
[2021-08-01 07:57:20 +0000] [10] [INFO] Booting worker with pid: 10
[2021-08-01 08:00:02 +0000] [7] [INFO] Starting gunicorn 20.1.0
[2021-08-01 08:00:02 +0000] [7] [INFO] Listening at: http://0.0.0.0:5000 (7)
[2021-08-01 08:00:02 +0000] [7] [INFO] Using worker: gthread
[2021-08-01 08:00:02 +0000] [9] [INFO] Booting worker with pid: 9
[2021-08-01 08:00:02 +0000] [10] [INFO] Booting worker with pid: 10
[2021-08-01 08:02:49 +0000] [7] [INFO] Starting gunicorn 20.1.0
[2021-08-01 08:02:49 +0000] [7] [INFO] Listening at: http://0.0.0.0:5000 (7)
[2021-08-01 08:02:49 +0000] [7] [INFO] Using worker: gthread
[2021-08-01 08:02:49 +0000] [9] [INFO] Booting worker with pid: 9
[2021-08-01 08:02:49 +0000] [10] [INFO] Booting worker with pid: 10
[2021-08-01 08:06:11 +0000] [7] [INFO] Starting gunicorn 20.1.0
[2021-08-01 08:06:11 +0000] [7] [INFO] Listening at: http://0.0.0.0:5000 (7)
[2021-08-01 08:06:11 +0000] [7] [INFO] Using worker: gthread
[2021-08-01 08:06:11 +0000] [9] [INFO] Booting worker with pid: 9
[2021-08-01 08:06:11 +0000] [10] [INFO] Booting worker with pid: 10
[2021-08-01 08:10:51 +0000] [9] [INFO] Starting gunicorn 20.1.0
[2021-08-01 08:10:51 +0000] [9] [INFO] Listening at: http://0.0.0.0:5000 (9)
[2021-08-01 08:10:51 +0000] [9] [INFO] Using worker: gthread
[2021-08-01 08:10:51 +0000] [11] [INFO] Booting worker with pid: 11
[2021-08-01 08:10:51 +0000] [12] [INFO] Booting worker with pid: 12
