[2021-07-10 11:28:28 +0000] [7] [INFO] Starting gunicorn 20.1.0
[2021-07-10 11:28:28 +0000] [7] [INFO] Listening at: http://0.0.0.0:5003 (7)
[2021-07-10 11:28:28 +0000] [7] [INFO] Using worker: gthread
[2021-07-10 11:28:28 +0000] [9] [INFO] Booting worker with pid: 9
[2021-07-10 11:28:28 +0000] [10] [INFO] Booting worker with pid: 10
[2021-07-10 11:30:56,406] ERROR in app: Exception on /post/comment [POST]
Traceback (most recent call last):
  File "/usr/local/lib/python3.8/site-packages/flask/app.py", line 2070, in wsgi_app
    response = self.full_dispatch_request()
  File "/usr/local/lib/python3.8/site-packages/flask/app.py", line 1515, in full_dispatch_request
    rv = self.handle_user_exception(e)
  File "/usr/local/lib/python3.8/site-packages/flask_cors/extension.py", line 165, in wrapped_function
    return cors_after_request(app.make_response(f(*args, **kwargs)))
  File "/usr/local/lib/python3.8/site-packages/flask/app.py", line 1513, in full_dispatch_request
    rv = self.dispatch_request()
  File "/usr/local/lib/python3.8/site-packages/flask/app.py", line 1499, in dispatch_request
    return self.ensure_sync(self.view_functions[rule.endpoint])(**req.view_args)
  File "/usr/local/lib/python3.8/site-packages/flask_jwt_extended/view_decorators.py", line 125, in decorator
    return current_app.ensure_sync(fn)(*args, **kwargs)
  File "/app/app/routes.py", line 114, in post_comment
    post.add_comment(request.json.get("card_id", None),request.json.get("comment", None))
  File "/app/app/models/posts_model.py", line 85, in add_comment
    c = Comment(post_id=self.pid,card_id=card_id, comment=comment)
  File "<string>", line 4, in __init__
  File "/usr/local/lib/python3.8/site-packages/sqlalchemy/orm/state.py", line 480, in _initialize_instance
    manager.dispatch.init_failure(self, args, kwargs)
  File "/usr/local/lib/python3.8/site-packages/sqlalchemy/util/langhelpers.py", line 70, in __exit__
    compat.raise_(
  File "/usr/local/lib/python3.8/site-packages/sqlalchemy/util/compat.py", line 207, in raise_
    raise exception
  File "/usr/local/lib/python3.8/site-packages/sqlalchemy/orm/state.py", line 477, in _initialize_instance
    return manager.original_init(*mixed[1:], **kwargs)
  File "/usr/local/lib/python3.8/site-packages/sqlalchemy/orm/decl_base.py", line 1142, in _declarative_constructor
    raise TypeError(
TypeError: 'comment' is an invalid keyword argument for Comment
[2021-07-10 11:36:28 +0000] [7] [INFO] Starting gunicorn 20.1.0
[2021-07-10 11:36:28 +0000] [7] [INFO] Listening at: http://0.0.0.0:5003 (7)
[2021-07-10 11:36:28 +0000] [7] [INFO] Using worker: gthread
[2021-07-10 11:36:28 +0000] [9] [INFO] Booting worker with pid: 9
[2021-07-10 11:36:28 +0000] [10] [INFO] Booting worker with pid: 10
[2021-07-10 11:38:36,055] ERROR in app: Exception on /post/comment [POST]
Traceback (most recent call last):
  File "/usr/local/lib/python3.8/site-packages/flask/app.py", line 2070, in wsgi_app
    response = self.full_dispatch_request()
  File "/usr/local/lib/python3.8/site-packages/flask/app.py", line 1515, in full_dispatch_request
    rv = self.handle_user_exception(e)
  File "/usr/local/lib/python3.8/site-packages/flask_cors/extension.py", line 165, in wrapped_function
    return cors_after_request(app.make_response(f(*args, **kwargs)))
  File "/usr/local/lib/python3.8/site-packages/flask/app.py", line 1513, in full_dispatch_request
    rv = self.dispatch_request()
  File "/usr/local/lib/python3.8/site-packages/flask/app.py", line 1499, in dispatch_request
    return self.ensure_sync(self.view_functions[rule.endpoint])(**req.view_args)
  File "/usr/local/lib/python3.8/site-packages/flask_jwt_extended/view_decorators.py", line 125, in decorator
    return current_app.ensure_sync(fn)(*args, **kwargs)
  File "/app/app/routes.py", line 114, in post_comment
    post.add_comment(request.json.get("card_id", None),request.json.get("comment", None))
  File "/app/app/models/posts_model.py", line 86, in add_comment
    c = Comment(post_id=self.pid,card_id=card_id,comment=comment)
  File "<string>", line 4, in __init__
  File "/usr/local/lib/python3.8/site-packages/sqlalchemy/orm/state.py", line 480, in _initialize_instance
    manager.dispatch.init_failure(self, args, kwargs)
  File "/usr/local/lib/python3.8/site-packages/sqlalchemy/util/langhelpers.py", line 70, in __exit__
    compat.raise_(
  File "/usr/local/lib/python3.8/site-packages/sqlalchemy/util/compat.py", line 207, in raise_
    raise exception
  File "/usr/local/lib/python3.8/site-packages/sqlalchemy/orm/state.py", line 477, in _initialize_instance
    return manager.original_init(*mixed[1:], **kwargs)
  File "/usr/local/lib/python3.8/site-packages/sqlalchemy/orm/decl_base.py", line 1142, in _declarative_constructor
    raise TypeError(
TypeError: 'comment' is an invalid keyword argument for Comment
[2021-07-10 11:54:17 +0000] [8] [INFO] Starting gunicorn 20.1.0
[2021-07-10 11:54:17 +0000] [8] [INFO] Listening at: http://0.0.0.0:5003 (8)
[2021-07-10 11:54:17 +0000] [8] [INFO] Using worker: gthread
[2021-07-10 11:54:17 +0000] [10] [INFO] Booting worker with pid: 10
[2021-07-10 11:54:17 +0000] [11] [INFO] Booting worker with pid: 11
[2021-07-10 11:58:47,767] ERROR in app: Exception on /post/comment/delete [POST]
Traceback (most recent call last):
  File "/usr/local/lib/python3.8/site-packages/flask/app.py", line 2070, in wsgi_app
    response = self.full_dispatch_request()
  File "/usr/local/lib/python3.8/site-packages/flask/app.py", line 1515, in full_dispatch_request
    rv = self.handle_user_exception(e)
  File "/usr/local/lib/python3.8/site-packages/flask_cors/extension.py", line 165, in wrapped_function
    return cors_after_request(app.make_response(f(*args, **kwargs)))
  File "/usr/local/lib/python3.8/site-packages/flask/app.py", line 1513, in full_dispatch_request
    rv = self.dispatch_request()
  File "/usr/local/lib/python3.8/site-packages/flask/app.py", line 1499, in dispatch_request
    return self.ensure_sync(self.view_functions[rule.endpoint])(**req.view_args)
  File "/usr/local/lib/python3.8/site-packages/flask_jwt_extended/view_decorators.py", line 125, in decorator
    return current_app.ensure_sync(fn)(*args, **kwargs)
TypeError: post_comment_delete() missing 1 required positional argument: 'coid'
[2021-07-10 12:04:01 +0000] [8] [INFO] Starting gunicorn 20.1.0
[2021-07-10 12:04:01 +0000] [8] [INFO] Listening at: http://0.0.0.0:5003 (8)
[2021-07-10 12:04:01 +0000] [8] [INFO] Using worker: gthread
[2021-07-10 12:04:01 +0000] [10] [INFO] Booting worker with pid: 10
[2021-07-10 12:04:01 +0000] [11] [INFO] Booting worker with pid: 11
[2021-07-10 12:04:22,658] ERROR in app: Exception on /post/comment/delete [POST]
Traceback (most recent call last):
  File "/usr/local/lib/python3.8/site-packages/flask/app.py", line 2070, in wsgi_app
    response = self.full_dispatch_request()
  File "/usr/local/lib/python3.8/site-packages/flask/app.py", line 1515, in full_dispatch_request
    rv = self.handle_user_exception(e)
  File "/usr/local/lib/python3.8/site-packages/flask_cors/extension.py", line 165, in wrapped_function
    return cors_after_request(app.make_response(f(*args, **kwargs)))
  File "/usr/local/lib/python3.8/site-packages/flask/app.py", line 1513, in full_dispatch_request
    rv = self.dispatch_request()
  File "/usr/local/lib/python3.8/site-packages/flask/app.py", line 1499, in dispatch_request
    return self.ensure_sync(self.view_functions[rule.endpoint])(**req.view_args)
  File "/usr/local/lib/python3.8/site-packages/flask_jwt_extended/view_decorators.py", line 125, in decorator
    return current_app.ensure_sync(fn)(*args, **kwargs)
TypeError: post_comment_delete() missing 1 required positional argument: 'coid'
[2021-07-10 12:06:46 +0000] [7] [INFO] Starting gunicorn 20.1.0
[2021-07-10 12:06:46 +0000] [7] [INFO] Listening at: http://0.0.0.0:5003 (7)
[2021-07-10 12:06:46 +0000] [7] [INFO] Using worker: gthread
[2021-07-10 12:06:46 +0000] [9] [INFO] Booting worker with pid: 9
[2021-07-10 12:06:46 +0000] [10] [INFO] Booting worker with pid: 10
